package net.killerchief.halocraft.worldGen;

import java.util.Random;
import net.killerchief.halocraft.Halocraft;
import net.killerchief.halocraft.comm.packetHandlers.PacketChat;
import net.killerchief.halocraft.config.HalocraftBlocks;
import net.killerchief.halocraft.config.HalocraftConfig;
import net.killerchief.halocraft.config.HalocraftItems;
import net.killerchief.halocraft.config.HalocraftItemsArmor;
import net.killerchief.halocraft.config.HalocraftItemsWeapons;
import net.killerchief.halocraft.entities.vehicles.EntityMongooseDefault;
import net.minecraft.block.Block;
import net.minecraft.init.Blocks;
import net.minecraft.item.ItemStack;
import net.minecraft.tileentity.TileEntityChest;
import net.minecraft.world.World;
import net.minecraft.world.WorldType;
import net.minecraft.world.biome.BiomeGenBase;
import cpw.mods.fml.common.network.NetworkRegistry;

public class WorldGenCrashedPelican extends WorldGenerator
{
	public WorldGenCrashedPelican(){}

	private int type = 0;
	private Block[] topTypes = {Blocks.grass, Blocks.sand};
	private Block[] groundTypes = {Blocks.dirt, Blocks.sand};

	private Block topType()
	{
		return this.topTypes[this.type];
	}

	private Block landType()
	{
		return this.groundTypes[this.type];
	}

	public boolean generate(World world, Random rand, int i, int j, int k)
	{
		BiomeGenBase biomeGen = world.getBiomeGenForCoords(i, k);
		if(biomeGen.biomeName != "Swampland" && (HalocraftConfig.CrashedPelicansInSuperFlat || world.getWorldInfo().getTerrainType() != WorldType.FLAT))
		{
			//System.out.println(biomeGen.topBlock);
			if (biomeGen.topBlock == Blocks.grass) {
				this.type = 0;
			} else if (biomeGen.topBlock == Blocks.sand) {
				this.type = 1;
			}
			
			if (/*Point 1 Start*/world.getBlock(i, j + 1, k) == this.landType() && world.getBlock(i, j + 2, k) == this.topType() && (this.type == 0 || (this.type == 1 && world.getBlock(i, j + 3, k) == Blocks.air)))
			{
				if (/*Point 2 Start*/world.getBlock(i + 35, j + 1, k) == this.landType() && world.getBlock(i + 35, j + 2, k) == this.topType() && (this.type == 0 || (this.type == 1 && world.getBlock(i + 35, j + 3, k) == Blocks.air)))
				{
					if (/*Point 3 Start*/world.getBlock(i, j + 1, k + 46) == this.landType() && world.getBlock(i, j + 2, k + 46) == this.topType() && (this.type == 0 || (this.type == 1 && world.getBlock(i, j + 3, k + 46) == Blocks.air)))
					{
						if (/*Point 4 Start*/world.getBlock(i + 35, j + 1, k + 46) == this.landType() && world.getBlock(i + 35, j + 2, k + 46) == this.topType() && (this.type == 0 || (this.type == 1 && world.getBlock(i + 35, j + 3, k + 46) == Blocks.air)))
						{
							if (world.getWorldInfo().getTerrainType() == WorldType.FLAT || (/*Point 5 Start*/world.getBlock(i + 18, j + 1, k + 23) == this.landType() && world.getBlock(i + 18, j + 2, k + 23) == this.topType() && (this.type == 0 || (this.type == 1 && world.getBlock(i + 18, j + 3, k + 23) == Blocks.air))))
							{
								this.HelmetMessages(world, rand, i, j, k);
								
								this.generate1(world, rand, i, j, k);
								
								return true;
							}
						}
					}
				}
			}
			return false;
		}
		return false;
	}
	
	public void HelmetMessages(World world, Random rand, int i, int j, int k)
	{
		//System.out.println("Pelican Spawned!");

		double radioRange = 300.0D;
		String text = "....*Static*......";
		int chance = rand.nextInt(4);
		if(chance == 0){
			text = "Mayday! Mayday! This is Pelican Dropship Delta.............";
		}else if(chance == 1){
			text = "Mayday! Mayday! Rear engines failing,....PULL UP!, PULL UP!.......";
		}else if(chance == 2){
			text = "We're hit! Mayday! Rear engines failing, we're going down!...";
		}else if(chance == 3){
			text = "...Ahhh, we're hit, we're hit! BAIL OUTTTT...*Static*.....";
		}else if(chance == 4){
			text = "....*Static*......";
		}
		Halocraft.network.sendToAllAround(new PacketChat(text), new NetworkRegistry.TargetPoint(world.provider.dimensionId, i, j, k, radioRange));
	}
	
	public void generate1(World world, Random rand, int i, int j, int k) {
		world.setBlock(i + 14, j + 2, k + 18, Blocks.air);
		world.setBlock(i + 14, j + 1, k + 18, Blocks.double_stone_slab);
		world.setBlock(i + 13, j + 2, k + 18, Blocks.double_stone_slab);
		world.setBlock(i + 14, j + 2, k + 17, Blocks.double_stone_slab);
		world.setBlock(i + 14, j + 2, k + 19, Blocks.double_stone_slab);
		world.setBlock(i + 15, j + 2, k + 18, Blocks.air);
		world.setBlock(i + 14, j + 2, k + 18, Blocks.chest);
		world.setBlockMetadataWithNotify(i + 14, j + 2, k + 18, 2, 2);
		TileEntityChest tileentitychest = (TileEntityChest)world.getTileEntity(i + 14, j + 2, k + 18);
		if(tileentitychest != null && tileentitychest.getSizeInventory() > 0)
		{
			tileentitychest.setInventorySlotContents(rand.nextInt(3), new ItemStack(HalocraftItems.ItemHealthPack));
			tileentitychest.setInventorySlotContents(rand.nextInt(3)+3, new ItemStack(HalocraftItems.UNSCPowerGenerator));
			tileentitychest.setInventorySlotContents(rand.nextInt(3)+6, new ItemStack(HalocraftItemsWeapons.FirebombGrenade, rand.nextInt(5)+1));

			tileentitychest.setInventorySlotContents(rand.nextInt(3)+12, new ItemStack(HalocraftItemsWeapons.FragGrenade, rand.nextInt(3)+1));
			int chance = rand.nextInt(6);
			if(chance == 0){
				tileentitychest.setInventorySlotContents(rand.nextInt(3)+15, new ItemStack(HalocraftItemsWeapons.BattleRifle));
				tileentitychest.setInventorySlotContents(rand.nextInt(3)+9, new ItemStack(HalocraftItemsWeapons.MediumRounds, rand.nextInt(20)+18));
			}else if(chance == 1){
				tileentitychest.setInventorySlotContents(rand.nextInt(3)+15, new ItemStack(HalocraftItemsWeapons.AssaultRifle));
				tileentitychest.setInventorySlotContents(rand.nextInt(3)+9, new ItemStack(HalocraftItemsWeapons.SmallRounds, rand.nextInt(24)+18));
			}else if(chance == 2){
				tileentitychest.setInventorySlotContents(rand.nextInt(3)+15, new ItemStack(HalocraftItemsWeapons.Shotgun));
				tileentitychest.setInventorySlotContents(rand.nextInt(3)+9, new ItemStack(HalocraftItemsWeapons.ShotgunRounds, rand.nextInt(22)+8));
			}else if(chance == 3){
				tileentitychest.setInventorySlotContents(rand.nextInt(3)+15, new ItemStack(HalocraftItemsWeapons.SniperRifle));
				tileentitychest.setInventorySlotContents(rand.nextInt(3)+9, new ItemStack(HalocraftItemsWeapons.LargeRounds, rand.nextInt(8)+8));
			}else if(chance == 4){
				tileentitychest.setInventorySlotContents(rand.nextInt(3)+15, new ItemStack(HalocraftItemsWeapons.Magnum));
				tileentitychest.setInventorySlotContents(rand.nextInt(3)+9, new ItemStack(HalocraftItemsWeapons.MediumRounds, rand.nextInt(26)+12));
			}else if(chance == 5){
				tileentitychest.setInventorySlotContents(rand.nextInt(3)+15, new ItemStack(HalocraftItemsWeapons.SMG));
				tileentitychest.setInventorySlotContents(rand.nextInt(3)+9, new ItemStack(HalocraftItemsWeapons.SmallRounds, rand.nextInt(26)+20));
			}else if(chance == 6){
				tileentitychest.setInventorySlotContents(rand.nextInt(3)+15, new ItemStack(HalocraftItemsWeapons.RocketLauncher));
				tileentitychest.setInventorySlotContents(rand.nextInt(3)+9, new ItemStack(HalocraftItemsWeapons.Rocket, rand.nextInt(4)+1));
			}else{
				tileentitychest.setInventorySlotContents(rand.nextInt(3)+15, new ItemStack(HalocraftItemsWeapons.Magnum));
				tileentitychest.setInventorySlotContents(rand.nextInt(3)+9, new ItemStack(HalocraftItemsWeapons.MediumRounds, rand.nextInt(26)+12));
			}

			tileentitychest.setInventorySlotContents(rand.nextInt(3)+18, new ItemStack(HalocraftItems.ShieldProjector));
			tileentitychest.setInventorySlotContents(rand.nextInt(3)+24, new ItemStack(HalocraftItemsArmor.HelmetUnderArmor));
			int ChipChance = rand.nextInt(3);
			if(ChipChance == 0){
				tileentitychest.setInventorySlotContents(rand.nextInt(3)+21, new ItemStack(HalocraftItems.DataStorageChip1));
			}else if(ChipChance == 1){
				tileentitychest.setInventorySlotContents(rand.nextInt(3)+21, new ItemStack(HalocraftItems.DataStorageChip1));
			}else if(ChipChance == 2){
				tileentitychest.setInventorySlotContents(rand.nextInt(3)+21, new ItemStack(HalocraftItems.DataStorageChip2));
			}else if(ChipChance == 3){
				tileentitychest.setInventorySlotContents(rand.nextInt(3)+21, new ItemStack(HalocraftItems.DataStorageChip2));
			}else{
				tileentitychest.setInventorySlotContents(rand.nextInt(3)+21, new ItemStack(HalocraftItems.DataStorageChip2));
			}
		}
		world.setBlock(i + 0, j + 0, k + 12, this.topType());
		world.setBlock(i + 0, j + 0, k + 13, this.topType());
		world.setBlock(i + 0, j + 0, k + 14, this.topType());
		world.setBlock(i + 0, j + 0, k + 15, this.topType());
		world.setBlock(i + 0, j + 0, k + 16, this.topType());
		world.setBlock(i + 0, j + 0, k + 17, this.topType());
		world.setBlock(i + 0, j + 0, k + 18, this.topType());
		world.setBlock(i + 0, j + 0, k + 19, this.topType());
		world.setBlock(i + 0, j + 0, k + 20, this.topType());
		world.setBlock(i + 0, j + 0, k + 21, this.topType());
		world.setBlock(i + 0, j + 0, k + 22, this.topType());
		world.setBlock(i + 1, j + 0, k + 9, this.topType());
		world.setBlock(i + 1, j + 0, k + 10, this.topType());
		world.setBlock(i + 1, j + 0, k + 11, this.topType());
		world.setBlock(i + 1, j + 0, k + 12, this.landType());
		world.setBlock(i + 1, j + 0, k + 13, this.landType());
		world.setBlock(i + 1, j + 0, k + 14, this.landType());
		world.setBlock(i + 1, j + 0, k + 15, this.landType());
		world.setBlock(i + 1, j + 0, k + 16, this.landType());
		world.setBlock(i + 1, j + 0, k + 17, this.landType());
		world.setBlock(i + 1, j + 0, k + 18, this.landType());
		world.setBlock(i + 1, j + 0, k + 19, this.landType());
		world.setBlock(i + 1, j + 0, k + 20, this.landType());
		world.setBlock(i + 1, j + 0, k + 21, this.landType());
		world.setBlock(i + 1, j + 0, k + 22, this.landType());
		world.setBlock(i + 1, j + 0, k + 23, this.topType());
		world.setBlock(i + 1, j + 0, k + 24, this.topType());
		world.setBlock(i + 1, j + 0, k + 25, this.topType());
		world.setBlock(i + 1, j + 1, k + 12, this.topType());
		world.setBlock(i + 1, j + 1, k + 13, this.topType());
		world.setBlock(i + 1, j + 1, k + 14, this.topType());
		world.setBlock(i + 1, j + 1, k + 15, this.topType());
		world.setBlock(i + 1, j + 1, k + 16, this.topType());
		world.setBlock(i + 1, j + 1, k + 17, this.topType());
		world.setBlock(i + 1, j + 1, k + 18, this.topType());
		world.setBlock(i + 1, j + 1, k + 19, this.topType());
		world.setBlock(i + 1, j + 1, k + 20, this.topType());
		world.setBlock(i + 1, j + 1, k + 21, this.topType());
		world.setBlock(i + 1, j + 1, k + 22, this.topType());
		world.setBlock(i + 2, j + 0, k + 8, this.topType());
		world.setBlock(i + 2, j + 0, k + 9, this.landType());
		world.setBlock(i + 2, j + 0, k + 10, this.landType());
		world.setBlock(i + 2, j + 0, k + 11, this.landType());
		world.setBlock(i + 2, j + 0, k + 12, this.landType());
		world.setBlock(i + 2, j + 0, k + 13, this.landType());
		world.setBlock(i + 2, j + 0, k + 14, this.landType());
		world.setBlock(i + 2, j + 0, k + 15, this.landType());
		world.setBlock(i + 2, j + 0, k + 16, this.landType());
		world.setBlock(i + 2, j + 0, k + 17, this.landType());
		world.setBlock(i + 2, j + 0, k + 18, this.landType());
		world.setBlock(i + 2, j + 0, k + 19, this.landType());
		world.setBlock(i + 2, j + 0, k + 20, this.landType());
		world.setBlock(i + 2, j + 0, k + 21, this.landType());
		world.setBlock(i + 2, j + 0, k + 22, this.landType());
		world.setBlock(i + 2, j + 0, k + 23, this.landType());
		world.setBlock(i + 2, j + 0, k + 24, this.landType());
		world.setBlock(i + 2, j + 0, k + 25, this.landType());
		world.setBlock(i + 2, j + 0, k + 26, this.topType());
		world.setBlock(i + 2, j + 1, k + 9, this.topType());
		world.setBlock(i + 2, j + 1, k + 10, this.topType());
		world.setBlock(i + 2, j + 1, k + 11, this.topType());
		world.setBlock(i + 2, j + 1, k + 12, this.landType());
		world.setBlock(i + 2, j + 1, k + 13, this.landType());
		world.setBlock(i + 2, j + 1, k + 14, this.landType());
		world.setBlock(i + 2, j + 1, k + 15, this.landType());
		world.setBlock(i + 2, j + 1, k + 16, this.landType());
		world.setBlock(i + 2, j + 1, k + 17, this.landType());
		world.setBlock(i + 2, j + 1, k + 18, this.landType());
		world.setBlock(i + 2, j + 1, k + 19, this.landType());
		world.setBlock(i + 2, j + 1, k + 20, this.landType());
		world.setBlock(i + 2, j + 1, k + 21, this.landType());
		world.setBlock(i + 2, j + 1, k + 22, this.landType());
		world.setBlock(i + 2, j + 1, k + 23, this.topType());
		world.setBlock(i + 2, j + 1, k + 24, this.topType());
		world.setBlock(i + 2, j + 1, k + 25, this.topType());
		world.setBlock(i + 2, j + 2, k + 12, this.topType());
		world.setBlock(i + 2, j + 2, k + 13, this.topType());
		world.setBlock(i + 2, j + 2, k + 14, this.topType());
		world.setBlock(i + 2, j + 2, k + 15, this.topType());
		world.setBlock(i + 2, j + 2, k + 16, this.topType());
		world.setBlock(i + 2, j + 2, k + 17, this.topType());
		world.setBlock(i + 2, j + 2, k + 18, this.topType());
		world.setBlock(i + 2, j + 2, k + 19, this.topType());
		world.setBlock(i + 2, j + 2, k + 20, this.topType());
		world.setBlock(i + 2, j + 2, k + 21, this.topType());
		world.setBlock(i + 2, j + 2, k + 22, this.topType());
		world.setBlock(i + 2, j + 3, k + 14, this.landType());
		world.setBlock(i + 2, j + 3, k + 20, this.landType());
		world.setBlock(i + 2, j + 4, k + 14, Blocks.fire);
		world.setBlock(i + 2, j + 4, k + 20, Blocks.fire);
		world.setBlock(i + 3, j + 0, k + 7, this.topType());
		world.setBlock(i + 3, j + 0, k + 8, this.landType());
		world.setBlock(i + 3, j + 0, k + 9, this.landType());
		world.setBlock(i + 3, j + 0, k + 10, this.landType());
		world.setBlock(i + 3, j + 0, k + 11, this.landType());
		world.setBlock(i + 3, j + 0, k + 12, this.landType());
		world.setBlock(i + 3, j + 0, k + 13, this.landType());
		world.setBlock(i + 3, j + 0, k + 14, this.landType());
		world.setBlock(i + 3, j + 0, k + 15, this.landType());
		world.setBlock(i + 3, j + 0, k + 16, this.landType());
		world.setBlock(i + 3, j + 0, k + 17, this.landType());
		world.setBlock(i + 3, j + 0, k + 18, this.landType());
		world.setBlock(i + 3, j + 0, k + 19, this.landType());
		world.setBlock(i + 3, j + 0, k + 20, this.landType());
		world.setBlock(i + 3, j + 0, k + 21, this.landType());
		world.setBlock(i + 3, j + 0, k + 22, this.landType());
		world.setBlock(i + 3, j + 0, k + 23, this.landType());
		world.setBlock(i + 3, j + 0, k + 24, this.landType());
		world.setBlock(i + 3, j + 0, k + 25, this.landType());
		world.setBlock(i + 3, j + 0, k + 26, this.landType());
		world.setBlock(i + 3, j + 0, k + 27, this.topType());
		world.setBlock(i + 3, j + 1, k + 8, this.topType());
		world.setBlock(i + 3, j + 1, k + 9, this.landType());
		world.setBlock(i + 3, j + 1, k + 10, this.landType());
		world.setBlock(i + 3, j + 1, k + 11, this.landType());
		world.setBlock(i + 3, j + 1, k + 12, this.landType());
		world.setBlock(i + 3, j + 1, k + 13, this.landType());
		world.setBlock(i + 3, j + 1, k + 14, this.landType());
		world.setBlock(i + 3, j + 1, k + 15, this.landType());
		world.setBlock(i + 3, j + 1, k + 16, this.landType());
		world.setBlock(i + 3, j + 1, k + 17, this.landType());
		world.setBlock(i + 3, j + 1, k + 18, this.landType());
		world.setBlock(i + 3, j + 1, k + 19, this.landType());
		world.setBlock(i + 3, j + 1, k + 20, this.landType());
		world.setBlock(i + 3, j + 1, k + 21, this.landType());
		world.setBlock(i + 3, j + 1, k + 22, this.landType());
		world.setBlock(i + 3, j + 1, k + 23, this.landType());
		world.setBlock(i + 3, j + 1, k + 24, this.landType());
		world.setBlock(i + 3, j + 1, k + 25, this.landType());
		world.setBlock(i + 3, j + 1, k + 26, this.topType());
		world.setBlock(i + 3, j + 2, k + 9, this.topType());
		world.setBlock(i + 3, j + 2, k + 10, this.topType());
		world.setBlock(i + 3, j + 2, k + 11, this.topType());
		world.setBlock(i + 3, j + 2, k + 12, this.topType());
		world.setBlock(i + 3, j + 2, k + 13, this.topType());
		world.setBlock(i + 3, j + 2, k + 14, this.topType());
		world.setBlock(i + 3, j + 2, k + 15, this.topType());
		world.setBlock(i + 3, j + 2, k + 16, this.topType());
		world.setBlock(i + 3, j + 2, k + 17, this.topType());
		world.setBlock(i + 3, j + 2, k + 18, this.topType());
		world.setBlock(i + 3, j + 2, k + 19, this.topType());
		world.setBlock(i + 3, j + 2, k + 20, this.topType());
		world.setBlock(i + 3, j + 2, k + 21, this.topType());
		world.setBlock(i + 3, j + 2, k + 22, this.topType());
		world.setBlock(i + 3, j + 2, k + 23, this.topType());
		world.setBlock(i + 3, j + 2, k + 24, this.topType());
		world.setBlock(i + 3, j + 2, k + 25, this.topType());
		world.setBlock(i + 3, j + 3, k + 13, this.landType());
		world.setBlock(i + 3, j + 3, k + 17, Blocks.fire);
		world.setBlock(i + 3, j + 3, k + 25, this.landType());
		world.setBlock(i + 3, j + 4, k + 13, Blocks.fire);
		world.setBlock(i + 3, j + 4, k + 25, Blocks.fire);
		world.setBlock(i + 4, j + 0, k + 6, this.topType());
		world.setBlock(i + 4, j + 0, k + 7, this.landType());
		world.setBlock(i + 4, j + 0, k + 8, this.landType());
		world.setBlock(i + 4, j + 0, k + 9, this.landType());
		world.setBlock(i + 4, j + 0, k + 10, this.landType());
		world.setBlock(i + 4, j + 0, k + 11, this.landType());
		world.setBlock(i + 4, j + 0, k + 12, this.landType());
		world.setBlock(i + 4, j + 0, k + 13, this.landType());
		world.setBlock(i + 4, j + 0, k + 14, this.landType());
		world.setBlock(i + 4, j + 0, k + 15, this.landType());
		world.setBlock(i + 4, j + 0, k + 16, this.landType());
		world.setBlock(i + 4, j + 0, k + 17, this.landType());
		world.setBlock(i + 4, j + 0, k + 18, this.landType());
		world.setBlock(i + 4, j + 0, k + 19, this.landType());
		world.setBlock(i + 4, j + 0, k + 20, this.landType());
		world.setBlock(i + 4, j + 0, k + 21, this.landType());
		world.setBlock(i + 4, j + 0, k + 22, this.landType());
		world.setBlock(i + 4, j + 0, k + 23, this.landType());
		world.setBlock(i + 4, j + 0, k + 24, this.landType());
		world.setBlock(i + 4, j + 0, k + 25, this.landType());
		world.setBlock(i + 4, j + 0, k + 26, this.landType());
		world.setBlock(i + 4, j + 0, k + 27, this.landType());
		world.setBlock(i + 4, j + 0, k + 28, this.topType());
		world.setBlock(i + 4, j + 1, k + 7, this.topType());
		world.setBlock(i + 4, j + 1, k + 8, this.landType());
		world.setBlock(i + 4, j + 1, k + 9, this.landType());
		world.setBlock(i + 4, j + 1, k + 10, this.landType());
		world.setBlock(i + 4, j + 1, k + 11, this.landType());
		world.setBlock(i + 4, j + 1, k + 12, this.landType());
		world.setBlock(i + 4, j + 1, k + 13, this.landType());
		world.setBlock(i + 4, j + 1, k + 14, this.landType());
		world.setBlock(i + 4, j + 1, k + 15, this.landType());
		world.setBlock(i + 4, j + 1, k + 16, this.landType());
		world.setBlock(i + 4, j + 1, k + 17, this.landType());
		world.setBlock(i + 4, j + 1, k + 18, this.landType());
		world.setBlock(i + 4, j + 1, k + 19, this.landType());
		world.setBlock(i + 4, j + 1, k + 20, this.landType());
		world.setBlock(i + 4, j + 1, k + 21, this.landType());
		world.setBlock(i + 4, j + 1, k + 22, this.landType());
		world.setBlock(i + 4, j + 1, k + 23, this.landType());
		world.setBlock(i + 4, j + 1, k + 24, this.landType());
		world.setBlock(i + 4, j + 1, k + 25, this.landType());
		world.setBlock(i + 4, j + 1, k + 26, this.landType());
		world.setBlock(i + 4, j + 1, k + 27, this.topType());
		world.setBlock(i + 4, j + 2, k + 8, this.topType());
		world.setBlock(i + 4, j + 2, k + 9, this.topType());
		world.setBlock(i + 4, j + 2, k + 10, this.topType());
		world.setBlock(i + 4, j + 2, k + 11, this.topType());
		world.setBlock(i + 4, j + 2, k + 12, this.topType());
		world.setBlock(i + 4, j + 2, k + 13, this.topType());
		world.setBlock(i + 4, j + 2, k + 14, this.topType());
		world.setBlock(i + 4, j + 2, k + 15, this.topType());
		world.setBlock(i + 4, j + 2, k + 16, this.topType());
		world.setBlock(i + 4, j + 2, k + 17, this.topType());
		world.setBlock(i + 4, j + 2, k + 18, this.topType());
		world.setBlock(i + 4, j + 2, k + 19, this.topType());
		world.setBlock(i + 4, j + 2, k + 20, this.topType());
		world.setBlock(i + 4, j + 2, k + 21, this.topType());
		world.setBlock(i + 4, j + 2, k + 22, this.topType());
		world.setBlock(i + 4, j + 2, k + 23, this.topType());
		world.setBlock(i + 4, j + 2, k + 24, this.topType());
		world.setBlock(i + 4, j + 2, k + 25, this.topType());
		world.setBlock(i + 4, j + 2, k + 26, this.topType());
		world.setBlock(i + 4, j + 3, k + 15, this.landType());
		world.setBlock(i + 4, j + 3, k + 16, this.landType());
		world.setBlock(i + 4, j + 3, k + 17, this.landType());
		world.setBlock(i + 4, j + 3, k + 18, this.landType());
		world.setBlock(i + 4, j + 3, k + 19, this.landType());
		world.setBlock(i + 4, j + 3, k + 23, Blocks.fire);
		world.setBlock(i + 4, j + 4, k + 16, Blocks.fire);
		world.setBlock(i + 5, j + 0, k + 5, this.topType());
		world.setBlock(i + 5, j + 0, k + 6, this.landType());
		world.setBlock(i + 5, j + 0, k + 7, this.landType());
		world.setBlock(i + 5, j + 0, k + 8, this.landType());
		world.setBlock(i + 5, j + 0, k + 9, this.landType());
		world.setBlock(i + 5, j + 0, k + 10, this.landType());
		world.setBlock(i + 5, j + 0, k + 11, this.landType());
		world.setBlock(i + 5, j + 0, k + 12, this.landType());
		world.setBlock(i + 5, j + 0, k + 13, this.landType());
		world.setBlock(i + 5, j + 0, k + 14, this.landType());
		world.setBlock(i + 5, j + 0, k + 15, this.landType());
		world.setBlock(i + 5, j + 0, k + 16, this.landType());
		world.setBlock(i + 5, j + 0, k + 17, this.landType());
		world.setBlock(i + 5, j + 0, k + 18, this.landType());
		world.setBlock(i + 5, j + 0, k + 19, this.landType());
		world.setBlock(i + 5, j + 0, k + 20, this.landType());
		world.setBlock(i + 5, j + 0, k + 21, this.landType());
		world.setBlock(i + 5, j + 0, k + 22, this.landType());
		world.setBlock(i + 5, j + 0, k + 23, this.landType());
		world.setBlock(i + 5, j + 0, k + 24, this.landType());
		world.setBlock(i + 5, j + 0, k + 25, this.landType());
		world.setBlock(i + 5, j + 0, k + 26, this.landType());
		world.setBlock(i + 5, j + 0, k + 27, this.landType());
		world.setBlock(i + 5, j + 0, k + 28, this.landType());
		world.setBlock(i + 5, j + 0, k + 29, this.topType());
		world.setBlock(i + 5, j + 1, k + 6, this.topType());
		world.setBlock(i + 5, j + 1, k + 7, this.landType());
		world.setBlock(i + 5, j + 1, k + 8, this.landType());
		world.setBlock(i + 5, j + 1, k + 9, this.landType());
		world.setBlock(i + 5, j + 1, k + 10, this.landType());
		world.setBlock(i + 5, j + 1, k + 11, this.landType());
		world.setBlock(i + 5, j + 1, k + 12, this.landType());
		world.setBlock(i + 5, j + 1, k + 13, this.landType());
		world.setBlock(i + 5, j + 1, k + 14, this.landType());
		world.setBlock(i + 5, j + 1, k + 15, this.landType());
		world.setBlock(i + 5, j + 1, k + 16, this.landType());
		world.setBlock(i + 5, j + 1, k + 17, this.landType());
		world.setBlock(i + 5, j + 1, k + 18, this.landType());
		world.setBlock(i + 5, j + 1, k + 19, this.landType());
		world.setBlock(i + 5, j + 1, k + 20, this.landType());
		world.setBlock(i + 5, j + 1, k + 21, this.landType());
		world.setBlock(i + 5, j + 1, k + 22, this.landType());
		world.setBlock(i + 5, j + 1, k + 23, this.landType());
		world.setBlock(i + 5, j + 1, k + 24, this.landType());
		world.setBlock(i + 5, j + 1, k + 25, this.landType());
		world.setBlock(i + 5, j + 1, k + 26, this.landType());
		world.setBlock(i + 5, j + 1, k + 27, this.landType());
		world.setBlock(i + 5, j + 1, k + 28, this.topType());
		world.setBlock(i + 5, j + 2, k + 7, this.topType());
		world.setBlock(i + 5, j + 2, k + 8, this.topType());
		world.setBlock(i + 5, j + 2, k + 9, this.topType());
		world.setBlock(i + 5, j + 2, k + 10, this.topType());
		world.setBlock(i + 5, j + 2, k + 11, this.topType());
		world.setBlock(i + 5, j + 2, k + 12, this.topType());
		world.setBlock(i + 5, j + 2, k + 13, this.topType());
		world.setBlock(i + 5, j + 2, k + 14, this.topType());
		world.setBlock(i + 5, j + 2, k + 15, this.topType());
		world.setBlock(i + 5, j + 2, k + 16, this.topType());
		world.setBlock(i + 5, j + 2, k + 17, this.topType());
		world.setBlock(i + 5, j + 2, k + 18, this.topType());
		world.setBlock(i + 5, j + 2, k + 19, this.topType());
		world.setBlock(i + 5, j + 2, k + 20, this.topType());
		world.setBlock(i + 5, j + 2, k + 21, this.topType());
		world.setBlock(i + 5, j + 2, k + 22, this.topType());
		world.setBlock(i + 5, j + 2, k + 23, this.topType());
		world.setBlock(i + 5, j + 2, k + 24, this.topType());
		world.setBlock(i + 5, j + 2, k + 25, this.topType());
		world.setBlock(i + 5, j + 2, k + 26, this.topType());
		world.setBlock(i + 5, j + 2, k + 27, this.topType());
		world.setBlock(i + 5, j + 3, k + 10, this.landType());
		world.setBlock(i + 5, j + 3, k + 12, Blocks.fire);
		world.setBlock(i + 5, j + 3, k + 14, this.landType());
		world.setBlock(i + 5, j + 3, k + 15, this.landType());
		world.setBlock(i + 5, j + 3, k + 16, this.landType());
		world.setBlock(i + 5, j + 3, k + 17, this.landType());
		world.setBlock(i + 5, j + 3, k + 18, this.landType());
		world.setBlock(i + 5, j + 3, k + 19, this.landType());
		world.setBlock(i + 5, j + 3, k + 20, this.landType());
		world.setBlock(i + 5, j + 4, k + 10, Blocks.fire);
		world.setBlock(i + 5, j + 4, k + 16, this.landType());
		world.setBlock(i + 5, j + 4, k + 17, this.landType());
		world.setBlock(i + 5, j + 4, k + 18, this.landType());
		world.setBlock(i + 5, j + 5, k + 18, Blocks.fire);
		world.setBlock(i + 6, j + 0, k + 4, this.topType());
		world.setBlock(i + 6, j + 0, k + 5, this.landType());
		world.setBlock(i + 6, j + 0, k + 6, this.landType());
		world.setBlock(i + 6, j + 0, k + 7, this.landType());
		world.setBlock(i + 6, j + 0, k + 8, this.landType());
		world.setBlock(i + 6, j + 0, k + 9, this.landType());
		world.setBlock(i + 6, j + 0, k + 10, this.landType());
		world.setBlock(i + 6, j + 0, k + 11, this.landType());
		world.setBlock(i + 6, j + 0, k + 12, this.landType());
		world.setBlock(i + 6, j + 0, k + 13, this.landType());
		world.setBlock(i + 6, j + 0, k + 14, this.landType());
		world.setBlock(i + 6, j + 0, k + 15, this.landType());
		world.setBlock(i + 6, j + 0, k + 16, this.landType());
		world.setBlock(i + 6, j + 0, k + 17, this.landType());
		world.setBlock(i + 6, j + 0, k + 18, this.landType());
		world.setBlock(i + 6, j + 0, k + 19, this.landType());
		world.setBlock(i + 6, j + 0, k + 20, this.landType());
		world.setBlock(i + 6, j + 0, k + 21, this.landType());
		world.setBlock(i + 6, j + 0, k + 22, this.landType());
		world.setBlock(i + 6, j + 0, k + 23, this.landType());
		world.setBlock(i + 6, j + 0, k + 24, this.landType());
		world.setBlock(i + 6, j + 0, k + 25, this.landType());
		world.setBlock(i + 6, j + 0, k + 26, this.landType());
		world.setBlock(i + 6, j + 0, k + 27, this.landType());
		world.setBlock(i + 6, j + 0, k + 28, this.landType());
		world.setBlock(i + 6, j + 0, k + 29, this.landType());
		world.setBlock(i + 6, j + 0, k + 30, this.topType());
		world.setBlock(i + 6, j + 1, k + 5, this.topType());
		world.setBlock(i + 6, j + 1, k + 6, this.landType());
		world.setBlock(i + 6, j + 1, k + 7, this.landType());
		world.setBlock(i + 6, j + 1, k + 8, this.landType());
		world.setBlock(i + 6, j + 1, k + 9, this.landType());
		world.setBlock(i + 6, j + 1, k + 10, this.landType());
		world.setBlock(i + 6, j + 1, k + 11, this.landType());
		world.setBlock(i + 6, j + 1, k + 12, this.landType());
		world.setBlock(i + 6, j + 1, k + 13, this.landType());
		world.setBlock(i + 6, j + 1, k + 14, this.landType());
		world.setBlock(i + 6, j + 1, k + 15, this.landType());
		world.setBlock(i + 6, j + 1, k + 16, this.landType());
		world.setBlock(i + 6, j + 1, k + 17, this.landType());
		world.setBlock(i + 6, j + 1, k + 18, this.landType());
		world.setBlock(i + 6, j + 1, k + 19, this.landType());
		world.setBlock(i + 6, j + 1, k + 20, this.landType());
		world.setBlock(i + 6, j + 1, k + 21, this.landType());
		world.setBlock(i + 6, j + 1, k + 22, this.landType());
		world.setBlock(i + 6, j + 1, k + 23, this.landType());
		world.setBlock(i + 6, j + 1, k + 24, this.landType());
		world.setBlock(i + 6, j + 1, k + 25, this.landType());
		world.setBlock(i + 6, j + 1, k + 26, this.landType());
		world.setBlock(i + 6, j + 1, k + 27, this.landType());
		world.setBlock(i + 6, j + 1, k + 28, this.landType());
		world.setBlock(i + 6, j + 1, k + 29, this.topType());
		world.setBlock(i + 6, j + 2, k + 6, this.topType());
		world.setBlock(i + 6, j + 2, k + 7, this.topType());
		world.setBlock(i + 6, j + 2, k + 8, this.topType());
		world.setBlock(i + 6, j + 2, k + 9, this.topType());
		world.setBlock(i + 6, j + 2, k + 10, this.topType());
		world.setBlock(i + 6, j + 2, k + 11, this.topType());
		world.setBlock(i + 6, j + 2, k + 12, this.topType());
		world.setBlock(i + 6, j + 2, k + 13, this.topType());
		world.setBlock(i + 6, j + 2, k + 14, this.topType());
		world.setBlock(i + 6, j + 2, k + 15, this.topType());
		world.setBlock(i + 6, j + 2, k + 16, this.topType());
		world.setBlock(i + 6, j + 2, k + 17, this.topType());
		world.setBlock(i + 6, j + 2, k + 18, this.topType());
		world.setBlock(i + 6, j + 2, k + 19, this.topType());
		world.setBlock(i + 6, j + 2, k + 20, this.topType());
		world.setBlock(i + 6, j + 2, k + 21, this.topType());
		world.setBlock(i + 6, j + 2, k + 22, this.topType());
		world.setBlock(i + 6, j + 2, k + 23, this.topType());
		world.setBlock(i + 6, j + 2, k + 24, this.topType());
		world.setBlock(i + 6, j + 2, k + 25, this.topType());
		world.setBlock(i + 6, j + 2, k + 26, this.topType());
		world.setBlock(i + 6, j + 2, k + 27, this.topType());
		world.setBlock(i + 6, j + 2, k + 28, this.topType());
		world.setBlock(i + 6, j + 3, k + 8, this.landType());
		world.setBlock(i + 6, j + 3, k + 13, this.landType());
		world.setBlock(i + 6, j + 3, k + 14, this.landType());
		world.setBlock(i + 6, j + 3, k + 15, this.landType());
		world.setBlock(i + 6, j + 3, k + 16, this.landType());
		world.setBlock(i + 6, j + 3, k + 17, this.landType());
		world.setBlock(i + 6, j + 3, k + 18, this.landType());
		world.setBlock(i + 6, j + 3, k + 19, this.landType());
		world.setBlock(i + 6, j + 3, k + 20, this.landType());
		world.setBlock(i + 6, j + 3, k + 21, this.landType());
		world.setBlock(i + 6, j + 3, k + 25, this.landType());
		world.setBlock(i + 6, j + 4, k + 8, Blocks.fire);
		world.setBlock(i + 6, j + 4, k + 14, Blocks.fire);
		world.setBlock(i + 6, j + 4, k + 15, this.landType());
		world.setBlock(i + 6, j + 4, k + 16, this.landType());
		world.setBlock(i + 6, j + 4, k + 17, this.landType());
		world.setBlock(i + 6, j + 4, k + 18, this.landType());
		world.setBlock(i + 6, j + 4, k + 19, this.landType());
		world.setBlock(i + 6, j + 4, k + 20, Blocks.fire);
		world.setBlock(i + 6, j + 4, k + 25, Blocks.fire);
		world.setBlock(i + 6, j + 5, k + 16, Blocks.fire);
		world.setBlock(i + 6, j + 5, k + 17, this.landType());
		world.setBlock(i + 6, j + 5, k + 18, this.landType());
		world.setBlock(i + 7, j + 0, k + 3, this.topType());
		world.setBlock(i + 7, j + 0, k + 4, this.landType());
		world.setBlock(i + 7, j + 0, k + 5, this.landType());
		world.setBlock(i + 7, j + 0, k + 6, this.landType());
		world.setBlock(i + 7, j + 0, k + 7, this.landType());
		world.setBlock(i + 7, j + 0, k + 8, this.landType());
		world.setBlock(i + 7, j + 0, k + 9, this.landType());
		world.setBlock(i + 7, j + 0, k + 10, this.landType());
		world.setBlock(i + 7, j + 0, k + 11, this.landType());
		world.setBlock(i + 7, j + 0, k + 12, this.landType());
		world.setBlock(i + 7, j + 0, k + 13, this.landType());
		world.setBlock(i + 7, j + 0, k + 14, this.landType());
		world.setBlock(i + 7, j + 0, k + 15, this.landType());
		world.setBlock(i + 7, j + 0, k + 16, this.landType());
		world.setBlock(i + 7, j + 0, k + 17, this.landType());
		world.setBlock(i + 7, j + 0, k + 18, this.landType());
		world.setBlock(i + 7, j + 0, k + 19, this.landType());
		world.setBlock(i + 7, j + 0, k + 20, this.landType());
		world.setBlock(i + 7, j + 0, k + 21, this.landType());
		world.setBlock(i + 7, j + 0, k + 22, this.landType());
		world.setBlock(i + 7, j + 0, k + 23, this.landType());
		world.setBlock(i + 7, j + 0, k + 24, this.landType());
		world.setBlock(i + 7, j + 0, k + 25, this.landType());
		world.setBlock(i + 7, j + 0, k + 26, this.landType());
		world.setBlock(i + 7, j + 0, k + 27, this.landType());
		world.setBlock(i + 7, j + 0, k + 28, this.landType());
		world.setBlock(i + 7, j + 0, k + 29, this.landType());
		world.setBlock(i + 7, j + 0, k + 30, this.landType());
		world.setBlock(i + 7, j + 0, k + 31, this.topType());
		world.setBlock(i + 7, j + 1, k + 4, this.topType());
		world.setBlock(i + 7, j + 1, k + 5, this.landType());
		world.setBlock(i + 7, j + 1, k + 6, this.landType());
		world.setBlock(i + 7, j + 1, k + 7, this.landType());
		world.setBlock(i + 7, j + 1, k + 8, this.landType());
		world.setBlock(i + 7, j + 1, k + 9, this.landType());
		world.setBlock(i + 7, j + 1, k + 10, this.landType());
		world.setBlock(i + 7, j + 1, k + 11, this.landType());
		world.setBlock(i + 7, j + 1, k + 12, this.landType());
		world.setBlock(i + 7, j + 1, k + 13, this.landType());
		world.setBlock(i + 7, j + 1, k + 14, this.landType());
		world.setBlock(i + 7, j + 1, k + 15, this.landType());
		world.setBlock(i + 7, j + 1, k + 16, this.landType());
		world.setBlock(i + 7, j + 1, k + 17, this.landType());
		world.setBlock(i + 7, j + 1, k + 18, this.landType());
		world.setBlock(i + 7, j + 1, k + 19, this.landType());
		world.setBlock(i + 7, j + 1, k + 20, this.landType());
		world.setBlock(i + 7, j + 1, k + 21, this.landType());
		world.setBlock(i + 7, j + 1, k + 22, this.landType());
		world.setBlock(i + 7, j + 1, k + 23, this.landType());
		world.setBlock(i + 7, j + 1, k + 24, this.landType());
		world.setBlock(i + 7, j + 1, k + 25, this.landType());
		world.setBlock(i + 7, j + 1, k + 26, this.landType());
		world.setBlock(i + 7, j + 1, k + 27, this.landType());
		world.setBlock(i + 7, j + 1, k + 28, this.landType());
		world.setBlock(i + 7, j + 1, k + 29, this.landType());
		world.setBlock(i + 7, j + 1, k + 30, this.topType());
		world.setBlock(i + 7, j + 2, k + 5, this.topType());
		world.setBlock(i + 7, j + 2, k + 6, this.topType());
		world.setBlock(i + 7, j + 2, k + 7, this.topType());
		world.setBlock(i + 7, j + 2, k + 8, this.topType());
		world.setBlock(i + 7, j + 2, k + 9, this.topType());
		world.setBlock(i + 7, j + 2, k + 10, this.topType());
		world.setBlock(i + 7, j + 2, k + 11, this.topType());
		world.setBlock(i + 7, j + 2, k + 12, this.topType());
		world.setBlock(i + 7, j + 2, k + 13, this.topType());
		world.setBlock(i + 7, j + 2, k + 14, this.topType());
		world.setBlock(i + 7, j + 2, k + 15, this.topType());
		world.setBlock(i + 7, j + 2, k + 16, this.topType());
		world.setBlock(i + 7, j + 2, k + 17, this.topType());
		world.setBlock(i + 7, j + 2, k + 18, this.topType());
		world.setBlock(i + 7, j + 2, k + 19, this.topType());
		world.setBlock(i + 7, j + 2, k + 20, this.topType());
		world.setBlock(i + 7, j + 2, k + 21, this.topType());
		world.setBlock(i + 7, j + 2, k + 22, this.topType());
		world.setBlock(i + 7, j + 2, k + 23, this.topType());
		world.setBlock(i + 7, j + 2, k + 24, this.topType());
		world.setBlock(i + 7, j + 2, k + 25, this.topType());
		world.setBlock(i + 7, j + 2, k + 26, this.topType());
		world.setBlock(i + 7, j + 2, k + 27, this.topType());
		world.setBlock(i + 7, j + 2, k + 28, this.topType());
		world.setBlock(i + 7, j + 2, k + 29, this.topType());
		world.setBlock(i + 7, j + 3, k + 12, this.landType());
		world.setBlock(i + 7, j + 3, k + 13, this.landType());
		world.setBlock(i + 7, j + 3, k + 14, this.landType());
		world.setBlock(i + 7, j + 3, k + 15, this.landType());
		world.setBlock(i + 7, j + 3, k + 16, this.landType());
		world.setBlock(i + 7, j + 3, k + 17, this.landType());
		world.setBlock(i + 7, j + 3, k + 18, this.landType());
		world.setBlock(i + 7, j + 3, k + 19, this.landType());
		world.setBlock(i + 7, j + 3, k + 20, this.landType());
		world.setBlock(i + 7, j + 3, k + 21, this.landType());
		world.setBlock(i + 7, j + 3, k + 22, this.landType());
		world.setBlock(i + 7, j + 3, k + 26, this.landType());
		world.setBlock(i + 7, j + 4, k + 13, Blocks.fire);
		world.setBlock(i + 7, j + 4, k + 14, this.landType());
		world.setBlock(i + 7, j + 4, k + 15, this.landType());
		world.setBlock(i + 7, j + 4, k + 16, this.landType());
		world.setBlock(i + 7, j + 4, k + 17, this.landType());
		world.setBlock(i + 7, j + 4, k + 18, this.landType());
		world.setBlock(i + 7, j + 4, k + 19, this.landType());
		world.setBlock(i + 7, j + 4, k + 20, this.landType());
		world.setBlock(i + 7, j + 4, k + 21, Blocks.fire);
		world.setBlock(i + 7, j + 4, k + 26, Blocks.fire);
		world.setBlock(i + 7, j + 5, k + 15, Blocks.fire);
		world.setBlock(i + 7, j + 5, k + 16, Blocks.fire);
		world.setBlock(i + 7, j + 5, k + 17, Blocks.air);
		world.setBlock(i + 7, j + 5, k + 18, Blocks.air);
		world.setBlock(i + 7, j + 5, k + 19, Blocks.fire);
		world.setBlock(i + 8, j + 0, k + 2, this.topType());
		world.setBlock(i + 8, j + 0, k + 3, this.landType());
		world.setBlock(i + 8, j + 0, k + 4, this.landType());
		world.setBlock(i + 8, j + 0, k + 5, this.landType());
		world.setBlock(i + 8, j + 0, k + 6, this.landType());
		world.setBlock(i + 8, j + 0, k + 7, this.landType());
		world.setBlock(i + 8, j + 0, k + 8, this.landType());
		world.setBlock(i + 8, j + 0, k + 9, this.landType());
		world.setBlock(i + 8, j + 0, k + 10, this.landType());
		world.setBlock(i + 8, j + 0, k + 11, this.landType());
		world.setBlock(i + 8, j + 0, k + 12, this.landType());
		world.setBlock(i + 8, j + 0, k + 13, this.landType());
		world.setBlock(i + 8, j + 0, k + 14, this.landType());
		world.setBlock(i + 8, j + 0, k + 15, this.landType());
		world.setBlock(i + 8, j + 0, k + 16, this.landType());
		world.setBlock(i + 8, j + 0, k + 17, this.landType());
		world.setBlock(i + 8, j + 0, k + 18, this.landType());
		world.setBlock(i + 8, j + 0, k + 19, this.landType());
		world.setBlock(i + 8, j + 0, k + 20, this.landType());
		world.setBlock(i + 8, j + 0, k + 21, this.landType());
		world.setBlock(i + 8, j + 0, k + 22, this.landType());
		world.setBlock(i + 8, j + 0, k + 23, this.landType());
		world.setBlock(i + 8, j + 0, k + 24, this.landType());
		world.setBlock(i + 8, j + 0, k + 25, this.landType());
		world.setBlock(i + 8, j + 0, k + 26, this.landType());
		world.setBlock(i + 8, j + 0, k + 27, this.landType());
		world.setBlock(i + 8, j + 0, k + 28, this.landType());
		world.setBlock(i + 8, j + 0, k + 29, this.landType());
		world.setBlock(i + 8, j + 0, k + 30, this.landType());
		world.setBlock(i + 8, j + 0, k + 31, this.landType());
		world.setBlock(i + 8, j + 0, k + 32, this.topType());
		world.setBlock(i + 8, j + 1, k + 3, this.topType());
		world.setBlock(i + 8, j + 1, k + 4, this.landType());
		world.setBlock(i + 8, j + 1, k + 5, this.landType());
		world.setBlock(i + 8, j + 1, k + 6, this.landType());
		world.setBlock(i + 8, j + 1, k + 7, this.landType());
		world.setBlock(i + 8, j + 1, k + 8, this.landType());
		world.setBlock(i + 8, j + 1, k + 9, this.landType());
		world.setBlock(i + 8, j + 1, k + 10, this.landType());
		world.setBlock(i + 8, j + 1, k + 11, this.landType());
		world.setBlock(i + 8, j + 1, k + 12, this.landType());
		world.setBlock(i + 8, j + 1, k + 13, this.landType());
		world.setBlock(i + 8, j + 1, k + 14, this.landType());
		world.setBlock(i + 8, j + 1, k + 15, this.landType());
		world.setBlock(i + 8, j + 1, k + 16, this.landType());
		world.setBlock(i + 8, j + 1, k + 17, Blocks.double_stone_slab);
		world.setBlock(i + 8, j + 1, k + 18, this.landType());
		world.setBlock(i + 8, j + 1, k + 19, this.landType());
		world.setBlock(i + 8, j + 1, k + 20, this.landType());
		world.setBlock(i + 8, j + 1, k + 21, this.landType());
		world.setBlock(i + 8, j + 1, k + 22, this.landType());
		world.setBlock(i + 8, j + 1, k + 23, this.landType());
		world.setBlock(i + 8, j + 1, k + 24, this.landType());
		world.setBlock(i + 8, j + 1, k + 25, this.landType());
		world.setBlock(i + 8, j + 1, k + 26, this.landType());
		world.setBlock(i + 8, j + 1, k + 27, this.landType());
		world.setBlock(i + 8, j + 1, k + 28, this.landType());
		world.setBlock(i + 8, j + 1, k + 29, this.landType());
		world.setBlock(i + 8, j + 1, k + 30, this.landType());
		world.setBlock(i + 8, j + 1, k + 31, this.topType());
		world.setBlock(i + 8, j + 2, k + 4, this.topType());
		world.setBlock(i + 8, j + 2, k + 5, this.topType());
		world.setBlock(i + 8, j + 2, k + 6, this.topType());
		world.setBlock(i + 8, j + 2, k + 7, this.topType());
		world.setBlock(i + 8, j + 2, k + 8, this.topType());
		world.setBlock(i + 8, j + 2, k + 9, this.topType());
		world.setBlock(i + 8, j + 2, k + 10, this.topType());
		world.setBlock(i + 8, j + 2, k + 11, this.topType());
		world.setBlock(i + 8, j + 2, k + 12, this.topType());
		world.setBlock(i + 8, j + 2, k + 13, this.topType());
		world.setBlock(i + 8, j + 2, k + 14, this.topType());
		world.setBlock(i + 8, j + 2, k + 15, this.topType());
		world.setBlock(i + 8, j + 2, k + 16, Blocks.double_stone_slab);
		world.setBlock(i + 8, j + 2, k + 17, Blocks.double_stone_slab);
		world.setBlock(i + 8, j + 2, k + 18, Blocks.double_stone_slab);
		world.setBlock(i + 8, j + 2, k + 19, this.topType());
		world.setBlock(i + 8, j + 2, k + 20, this.topType());
		world.setBlock(i + 8, j + 2, k + 21, this.topType());
		world.setBlock(i + 8, j + 2, k + 22, this.topType());
		world.setBlock(i + 8, j + 2, k + 23, this.topType());
		world.setBlock(i + 8, j + 2, k + 24, this.topType());
		world.setBlock(i + 8, j + 2, k + 25, this.topType());
		world.setBlock(i + 8, j + 2, k + 26, this.topType());
		world.setBlock(i + 8, j + 2, k + 27, this.topType());
		world.setBlock(i + 8, j + 2, k + 28, this.topType());
		world.setBlock(i + 8, j + 2, k + 29, this.topType());
		world.setBlock(i + 8, j + 2, k + 30, this.topType());
		world.setBlock(i + 8, j + 3, k + 9, Blocks.fire);
		world.setBlock(i + 8, j + 3, k + 11, this.landType());
		world.setBlock(i + 8, j + 3, k + 12, this.landType());
		world.setBlock(i + 8, j + 3, k + 13, this.landType());
		world.setBlock(i + 8, j + 3, k + 14, this.landType());
		world.setBlock(i + 8, j + 3, k + 15, this.landType());
		world.setBlock(i + 8, j + 3, k + 16, this.landType());
		world.setBlock(i + 8, j + 3, k + 17, this.landType());
		world.setBlock(i + 8, j + 3, k + 18, this.landType());
		world.setBlock(i + 8, j + 3, k + 19, this.landType());
		world.setBlock(i + 8, j + 3, k + 20, this.landType());
		world.setBlock(i + 8, j + 3, k + 21, this.landType());
		world.setBlock(i + 8, j + 3, k + 22, this.landType());
		world.setBlock(i + 8, j + 3, k + 23, this.landType());
		world.setBlock(i + 8, j + 3, k + 28, Blocks.fire);
		world.setBlock(i + 8, j + 4, k + 12, Blocks.air);
		world.setBlock(i + 8, j + 4, k + 13, this.landType());
		world.setBlock(i + 8, j + 4, k + 14, this.landType());
		world.setBlock(i + 8, j + 4, k + 15, this.landType());
		world.setBlock(i + 8, j + 4, k + 16, Blocks.fire);
		world.setBlock(i + 8, j + 4, k + 17, Blocks.fire);
		world.setBlock(i + 8, j + 4, k + 18, Blocks.fire);
		world.setBlock(i + 8, j + 4, k + 19, this.landType());
		world.setBlock(i + 8, j + 4, k + 20, this.landType());
		world.setBlock(i + 8, j + 4, k + 21, this.landType());
		world.setBlock(i + 8, j + 4, k + 22, Blocks.air);
		world.setBlock(i + 8, j + 5, k + 12, Blocks.fire);
		world.setBlock(i + 8, j + 5, k + 13, Blocks.air);
		world.setBlock(i + 8, j + 5, k + 14, this.landType());
		world.setBlock(i + 8, j + 5, k + 15, Blocks.air);
		world.setBlock(i + 8, j + 5, k + 16, Blocks.air);
		world.setBlock(i + 8, j + 5, k + 17, Blocks.air);
		world.setBlock(i + 8, j + 5, k + 18, Blocks.air);
		world.setBlock(i + 8, j + 5, k + 19, Blocks.air);
		world.setBlock(i + 8, j + 5, k + 20, Blocks.air);
		world.setBlock(i + 8, j + 5, k + 21, Blocks.air);
		world.setBlock(i + 8, j + 6, k + 14, Blocks.fire);
		world.setBlock(i + 8, j + 6, k + 16, Blocks.air);
		world.setBlock(i + 8, j + 6, k + 17, Blocks.air);
		world.setBlock(i + 8, j + 6, k + 18, Blocks.air);
		world.setBlock(i + 8, j + 6, k + 20, Blocks.fire);
		world.setBlock(i + 8, j + 7, k + 17, Blocks.fire);
		world.setBlock(i + 9, j + 0, k + 2, this.topType());
		world.setBlock(i + 9, j + 0, k + 3, this.landType());
		world.setBlock(i + 9, j + 0, k + 4, this.landType());
		world.setBlock(i + 9, j + 0, k + 5, this.landType());
		world.setBlock(i + 9, j + 0, k + 6, this.landType());
		world.setBlock(i + 9, j + 0, k + 7, this.landType());
		world.setBlock(i + 9, j + 0, k + 8, this.landType());
		world.setBlock(i + 9, j + 0, k + 9, this.landType());
		world.setBlock(i + 9, j + 0, k + 10, this.landType());
		world.setBlock(i + 9, j + 0, k + 11, this.landType());
		world.setBlock(i + 9, j + 0, k + 12, this.landType());
		world.setBlock(i + 9, j + 0, k + 13, this.landType());
		world.setBlock(i + 9, j + 0, k + 14, this.landType());
		world.setBlock(i + 9, j + 0, k + 15, this.landType());
		world.setBlock(i + 9, j + 0, k + 16, this.landType());
		world.setBlock(i + 9, j + 0, k + 17, this.landType());
		world.setBlock(i + 9, j + 0, k + 18, this.landType());
		world.setBlock(i + 9, j + 0, k + 19, this.landType());
		world.setBlock(i + 9, j + 0, k + 20, this.landType());
		world.setBlock(i + 9, j + 0, k + 21, this.landType());
		world.setBlock(i + 9, j + 0, k + 22, this.landType());
		world.setBlock(i + 9, j + 0, k + 23, this.landType());
		world.setBlock(i + 9, j + 0, k + 24, this.landType());
		world.setBlock(i + 9, j + 0, k + 25, this.landType());
		world.setBlock(i + 9, j + 0, k + 26, this.landType());
		world.setBlock(i + 9, j + 0, k + 27, this.landType());
		world.setBlock(i + 9, j + 0, k + 28, this.landType());
		world.setBlock(i + 9, j + 0, k + 29, this.landType());
		world.setBlock(i + 9, j + 0, k + 30, this.landType());
		world.setBlock(i + 9, j + 0, k + 31, this.landType());
		world.setBlock(i + 9, j + 0, k + 32, this.topType());
		world.setBlock(i + 9, j + 1, k + 3, this.topType());
		world.setBlock(i + 9, j + 1, k + 4, this.landType());
		world.setBlock(i + 9, j + 1, k + 5, this.landType());
		world.setBlock(i + 9, j + 1, k + 6, this.landType());
		world.setBlock(i + 9, j + 1, k + 7, this.landType());
		world.setBlock(i + 9, j + 1, k + 8, this.landType());
		world.setBlock(i + 9, j + 1, k + 9, this.landType());
		world.setBlock(i + 9, j + 1, k + 10, this.landType());
		world.setBlock(i + 9, j + 1, k + 11, this.landType());
		world.setBlock(i + 9, j + 1, k + 12, this.landType());
		world.setBlock(i + 9, j + 1, k + 13, this.landType());
		world.setBlock(i + 9, j + 1, k + 14, this.landType());
		world.setBlock(i + 9, j + 1, k + 15, this.landType());
		world.setBlock(i + 9, j + 1, k + 16, Blocks.double_stone_slab);
		world.setBlock(i + 9, j + 1, k + 17, Blocks.double_stone_slab);
		world.setBlock(i + 9, j + 1, k + 18, Blocks.double_stone_slab);
		world.setBlock(i + 9, j + 1, k + 19, this.landType());
		world.setBlock(i + 9, j + 1, k + 20, this.landType());
		world.setBlock(i + 9, j + 1, k + 21, this.landType());
		world.setBlock(i + 9, j + 1, k + 22, this.landType());
		world.setBlock(i + 9, j + 1, k + 23, this.landType());
		world.setBlock(i + 9, j + 1, k + 24, this.landType());
		world.setBlock(i + 9, j + 1, k + 25, this.landType());
		world.setBlock(i + 9, j + 1, k + 26, this.landType());
		world.setBlock(i + 9, j + 1, k + 27, this.landType());
		world.setBlock(i + 9, j + 1, k + 28, this.landType());
		world.setBlock(i + 9, j + 1, k + 29, this.landType());
		world.setBlock(i + 9, j + 1, k + 30, this.landType());
		world.setBlock(i + 9, j + 1, k + 31, this.topType());
		world.setBlock(i + 9, j + 2, k + 4, this.topType());
		world.setBlock(i + 9, j + 2, k + 5, this.topType());
		world.setBlock(i + 9, j + 2, k + 6, this.topType());
		world.setBlock(i + 9, j + 2, k + 7, this.topType());
		world.setBlock(i + 9, j + 2, k + 8, this.topType());
		world.setBlock(i + 9, j + 2, k + 9, this.topType());
		world.setBlock(i + 9, j + 2, k + 10, this.topType());
		world.setBlock(i + 9, j + 2, k + 11, this.topType());
		world.setBlock(i + 9, j + 2, k + 12, this.topType());
		world.setBlock(i + 9, j + 2, k + 13, this.topType());
		world.setBlock(i + 9, j + 2, k + 14, this.topType());
		world.setBlock(i + 9, j + 2, k + 15, Blocks.double_stone_slab);
		world.setBlock(i + 9, j + 2, k + 16, Blocks.double_stone_slab);
		world.setBlock(i + 9, j + 2, k + 17, Blocks.double_stone_slab);
		world.setBlock(i + 9, j + 2, k + 18, Blocks.double_stone_slab);
		world.setBlock(i + 9, j + 2, k + 19, Blocks.double_stone_slab);
		world.setBlock(i + 9, j + 2, k + 20, this.topType());
		world.setBlock(i + 9, j + 2, k + 21, this.topType());
		world.setBlock(i + 9, j + 2, k + 22, this.topType());
		world.setBlock(i + 9, j + 2, k + 23, this.topType());
		world.setBlock(i + 9, j + 2, k + 24, this.topType());
		world.setBlock(i + 9, j + 2, k + 25, this.topType());
		world.setBlock(i + 9, j + 2, k + 26, this.topType());
		world.setBlock(i + 9, j + 2, k + 27, this.topType());
		world.setBlock(i + 9, j + 2, k + 28, this.topType());
		world.setBlock(i + 9, j + 2, k + 29, this.topType());
		world.setBlock(i + 9, j + 2, k + 30, this.topType());
		world.setBlock(i + 9, j + 3, k + 5, Blocks.fire);
		world.setBlock(i + 9, j + 3, k + 7, this.landType());
		world.setBlock(i + 9, j + 3, k + 10, this.landType());
		world.setBlock(i + 9, j + 3, k + 11, this.landType());
		world.setBlock(i + 9, j + 3, k + 12, this.landType());
		world.setBlock(i + 9, j + 3, k + 13, this.landType());
		world.setBlock(i + 9, j + 3, k + 14, this.landType());
		world.setBlock(i + 9, j + 3, k + 15, this.landType());
		world.setBlock(i + 9, j + 3, k + 16, Blocks.glass);
		world.setBlock(i + 9, j + 3, k + 17, Blocks.glass);
		world.setBlock(i + 9, j + 3, k + 18, Blocks.glass);
		world.setBlock(i + 9, j + 3, k + 19, this.landType());
		world.setBlock(i + 9, j + 3, k + 20, this.landType());
		world.setBlock(i + 9, j + 3, k + 21, this.landType());
		world.setBlock(i + 9, j + 3, k + 22, this.landType());
		world.setBlock(i + 9, j + 3, k + 23, this.landType());
		world.setBlock(i + 9, j + 3, k + 24, this.landType());
		world.setBlock(i + 9, j + 4, k + 7, Blocks.fire);
		world.setBlock(i + 9, j + 4, k + 11, Blocks.air);
		world.setBlock(i + 9, j + 4, k + 12, this.landType());
		world.setBlock(i + 9, j + 4, k + 13, this.landType());
		world.setBlock(i + 9, j + 4, k + 14, this.landType());
		world.setBlock(i + 9, j + 4, k + 15, Blocks.air);
		world.setBlock(i + 9, j + 4, k + 16, Blocks.air);
		world.setBlock(i + 9, j + 4, k + 17, Blocks.air);
		world.setBlock(i + 9, j + 4, k + 18, Blocks.air);
		world.setBlock(i + 9, j + 4, k + 19, Blocks.air);
		world.setBlock(i + 9, j + 4, k + 20, this.landType());
		world.setBlock(i + 9, j + 4, k + 21, this.landType());
		world.setBlock(i + 9, j + 4, k + 22, this.landType());
		world.setBlock(i + 9, j + 4, k + 23, Blocks.air);
		world.setBlock(i + 9, j + 5, k + 11, Blocks.fire);
		world.setBlock(i + 9, j + 5, k + 12, Blocks.air);
		world.setBlock(i + 9, j + 5, k + 13, this.landType());
		world.setBlock(i + 9, j + 5, k + 14, Blocks.air);
		world.setBlock(i + 9, j + 5, k + 15, Blocks.air);
		world.setBlock(i + 9, j + 5, k + 16, Blocks.air);
		world.setBlock(i + 9, j + 5, k + 17, Blocks.air);
		world.setBlock(i + 9, j + 5, k + 18, Blocks.air);
		world.setBlock(i + 9, j + 5, k + 19, Blocks.air);
		world.setBlock(i + 9, j + 5, k + 20, Blocks.air);
		world.setBlock(i + 9, j + 5, k + 21, Blocks.air);
		world.setBlock(i + 9, j + 5, k + 22, Blocks.fire);
		world.setBlock(i + 9, j + 6, k + 13, Blocks.fire);
		world.setBlock(i + 9, j + 6, k + 14, Blocks.air);
		world.setBlock(i + 9, j + 6, k + 15, Blocks.air);
		world.setBlock(i + 9, j + 6, k + 16, Blocks.air);
		world.setBlock(i + 9, j + 6, k + 17, Blocks.air);
		world.setBlock(i + 9, j + 6, k + 18, Blocks.air);
		world.setBlock(i + 9, j + 6, k + 19, Blocks.air);
		world.setBlock(i + 9, j + 6, k + 20, Blocks.air);
		world.setBlock(i + 9, j + 6, k + 21, Blocks.air);
		world.setBlock(i + 9, j + 7, k + 14, Blocks.fire);
		world.setBlock(i + 9, j + 7, k + 16, Blocks.fire);
		world.setBlock(i + 9, j + 7, k + 17, Blocks.fire);
		world.setBlock(i + 9, j + 7, k + 18, Blocks.fire);
		world.setBlock(i + 9, j + 7, k + 19, Blocks.fire);
		world.setBlock(i + 10, j + 0, k + 1, this.topType());
		world.setBlock(i + 10, j + 0, k + 2, this.landType());
		world.setBlock(i + 10, j + 0, k + 3, this.landType());
		world.setBlock(i + 10, j + 0, k + 4, this.landType());
		world.setBlock(i + 10, j + 0, k + 5, this.landType());
		world.setBlock(i + 10, j + 0, k + 6, this.landType());
		world.setBlock(i + 10, j + 0, k + 7, this.landType());
		world.setBlock(i + 10, j + 0, k + 8, this.landType());
		world.setBlock(i + 10, j + 0, k + 9, this.landType());
		world.setBlock(i + 10, j + 0, k + 10, this.landType());
		world.setBlock(i + 10, j + 0, k + 11, this.landType());
		world.setBlock(i + 10, j + 0, k + 12, this.landType());
		world.setBlock(i + 10, j + 0, k + 13, this.landType());
		world.setBlock(i + 10, j + 0, k + 14, this.landType());
		world.setBlock(i + 10, j + 0, k + 15, this.landType());
		world.setBlock(i + 10, j + 0, k + 16, this.landType());
		world.setBlock(i + 10, j + 0, k + 17, this.landType());
		world.setBlock(i + 10, j + 0, k + 18, this.landType());
		world.setBlock(i + 10, j + 0, k + 19, this.landType());
		world.setBlock(i + 10, j + 0, k + 20, this.landType());
		world.setBlock(i + 10, j + 0, k + 21, this.landType());
		world.setBlock(i + 10, j + 0, k + 22, this.landType());
		world.setBlock(i + 10, j + 0, k + 23, this.landType());
		world.setBlock(i + 10, j + 0, k + 24, this.landType());
		world.setBlock(i + 10, j + 0, k + 25, this.landType());
		world.setBlock(i + 10, j + 0, k + 26, this.landType());
		world.setBlock(i + 10, j + 0, k + 27, this.landType());
		world.setBlock(i + 10, j + 0, k + 28, this.landType());
		world.setBlock(i + 10, j + 0, k + 29, this.landType());
		world.setBlock(i + 10, j + 0, k + 30, this.landType());
		world.setBlock(i + 10, j + 0, k + 31, this.landType());
		world.setBlock(i + 10, j + 0, k + 32, this.landType());
		world.setBlock(i + 10, j + 0, k + 33, this.topType());
		world.setBlock(i + 10, j + 1, k + 2, this.topType());
		world.setBlock(i + 10, j + 1, k + 3, this.landType());
		world.setBlock(i + 10, j + 1, k + 4, this.landType());
		world.setBlock(i + 10, j + 1, k + 5, this.landType());
		world.setBlock(i + 10, j + 1, k + 6, this.landType());
		world.setBlock(i + 10, j + 1, k + 7, this.landType());
		world.setBlock(i + 10, j + 1, k + 8, this.landType());
		world.setBlock(i + 10, j + 1, k + 9, this.landType());
		world.setBlock(i + 10, j + 1, k + 10, this.landType());
		world.setBlock(i + 10, j + 1, k + 11, this.landType());
		world.setBlock(i + 10, j + 1, k + 12, this.landType());
		world.setBlock(i + 10, j + 1, k + 13, this.landType());
		world.setBlock(i + 10, j + 1, k + 14, this.landType());
		world.setBlock(i + 10, j + 1, k + 15, this.landType());
		world.setBlock(i + 10, j + 1, k + 16, Blocks.double_stone_slab);
		world.setBlock(i + 10, j + 1, k + 17, Blocks.double_stone_slab);
		world.setBlock(i + 10, j + 1, k + 18, Blocks.double_stone_slab);
		world.setBlock(i + 10, j + 1, k + 19, this.landType());
		world.setBlock(i + 10, j + 1, k + 20, this.landType());
		world.setBlock(i + 10, j + 1, k + 21, this.landType());
		world.setBlock(i + 10, j + 1, k + 22, this.landType());
		world.setBlock(i + 10, j + 1, k + 23, this.landType());
		world.setBlock(i + 10, j + 1, k + 24, this.landType());
		world.setBlock(i + 10, j + 1, k + 25, this.landType());
		world.setBlock(i + 10, j + 1, k + 26, this.landType());
		world.setBlock(i + 10, j + 1, k + 27, this.landType());
		world.setBlock(i + 10, j + 1, k + 28, this.landType());
		world.setBlock(i + 10, j + 1, k + 29, this.landType());
		world.setBlock(i + 10, j + 1, k + 30, this.landType());
		world.setBlock(i + 10, j + 1, k + 31, this.landType());
		world.setBlock(i + 10, j + 1, k + 32, this.topType());
		world.setBlock(i + 10, j + 2, k + 3, this.topType());
		world.setBlock(i + 10, j + 2, k + 4, this.topType());
		world.setBlock(i + 10, j + 2, k + 5, this.topType());
		world.setBlock(i + 10, j + 2, k + 6, this.topType());
		world.setBlock(i + 10, j + 2, k + 7, this.topType());
		world.setBlock(i + 10, j + 2, k + 8, this.topType());
		world.setBlock(i + 10, j + 2, k + 9, this.topType());
		world.setBlock(i + 10, j + 2, k + 10, this.topType());
		world.setBlock(i + 10, j + 2, k + 11, this.topType());
		world.setBlock(i + 10, j + 2, k + 12, this.topType());
		world.setBlock(i + 10, j + 2, k + 13, this.topType());
		world.setBlock(i + 10, j + 2, k + 14, this.topType());
		world.setBlock(i + 10, j + 2, k + 15, Blocks.double_stone_slab);
		world.setBlock(i + 10, j + 2, k + 16, HalocraftBlocks.MetalLadder);
		world.setBlockMetadataWithNotify(i + 10, j + 2, k + 16, 2, 3); 
		world.setBlock(i + 10, j + 2, k + 17, Blocks.double_stone_slab);
		world.setBlock(i + 10, j + 2, k + 18, Blocks.double_stone_slab);
		world.setBlock(i + 10, j + 2, k + 19, Blocks.double_stone_slab);
		world.setBlock(i + 10, j + 2, k + 20, this.topType());
		world.setBlock(i + 10, j + 2, k + 21, this.topType());
		world.setBlock(i + 10, j + 2, k + 22, this.topType());
		world.setBlock(i + 10, j + 2, k + 23, this.topType());
		world.setBlock(i + 10, j + 2, k + 24, this.topType());
		world.setBlock(i + 10, j + 2, k + 25, this.topType());
		world.setBlock(i + 10, j + 2, k + 26, this.topType());
		world.setBlock(i + 10, j + 2, k + 27, this.topType());
		world.setBlock(i + 10, j + 2, k + 28, this.topType());
		world.setBlock(i + 10, j + 2, k + 29, this.topType());
		world.setBlock(i + 10, j + 2, k + 30, this.topType());
		world.setBlock(i + 10, j + 2, k + 31, this.topType());
		world.setBlock(i + 10, j + 3, k + 10, this.landType());
		world.setBlock(i + 10, j + 3, k + 11, this.landType());
		world.setBlock(i + 10, j + 3, k + 12, this.landType());
		world.setBlock(i + 10, j + 3, k + 13, this.landType());
		world.setBlock(i + 10, j + 3, k + 14, this.landType());
		world.setBlock(i + 10, j + 3, k + 15, Blocks.glass);
		world.setBlock(i + 10, j + 3, k + 16, Blocks.air);
		world.setBlock(i + 10, j + 3, k + 17, Blocks.air);
		world.setBlock(i + 10, j + 3, k + 18, Blocks.air);
		world.setBlock(i + 10, j + 3, k + 19, Blocks.glass);
		world.setBlock(i + 10, j + 3, k + 20, this.landType());
		world.setBlock(i + 10, j + 3, k + 21, this.landType());
		world.setBlock(i + 10, j + 3, k + 22, this.landType());
		world.setBlock(i + 10, j + 3, k + 23, this.landType());
		world.setBlock(i + 10, j + 3, k + 24, this.landType());
		world.setBlock(i + 10, j + 3, k + 27, Blocks.fire);
		world.setBlock(i + 10, j + 3, k + 30, this.landType());
		world.setBlock(i + 10, j + 4, k + 10, Blocks.air);
		world.setBlock(i + 10, j + 4, k + 11, this.landType());
		world.setBlock(i + 10, j + 4, k + 12, this.landType());
		world.setBlock(i + 10, j + 4, k + 13, this.landType());
		world.setBlock(i + 10, j + 4, k + 14, Blocks.air);
		world.setBlock(i + 10, j + 4, k + 15, Blocks.air);
		world.setBlock(i + 10, j + 4, k + 16, Blocks.glass);
		world.setBlock(i + 10, j + 4, k + 17, Blocks.glass);
		world.setBlock(i + 10, j + 4, k + 18, Blocks.glass);
		world.setBlock(i + 10, j + 4, k + 19, Blocks.air);
		world.setBlock(i + 10, j + 4, k + 20, Blocks.air);
		world.setBlock(i + 10, j + 4, k + 21, this.landType());
		world.setBlock(i + 10, j + 4, k + 22, this.landType());
		world.setBlock(i + 10, j + 4, k + 23, this.landType());
		world.setBlock(i + 10, j + 4, k + 24, Blocks.air);
		world.setBlock(i + 10, j + 4, k + 30, Blocks.fire);
		world.setBlock(i + 10, j + 5, k + 11, Blocks.air);
		world.setBlock(i + 10, j + 5, k + 12, this.landType());
		world.setBlock(i + 10, j + 5, k + 13, Blocks.air);
		world.setBlock(i + 10, j + 5, k + 14, Blocks.air);
		world.setBlock(i + 10, j + 5, k + 15, Blocks.air);
		world.setBlock(i + 10, j + 5, k + 16, Blocks.air);
		world.setBlock(i + 10, j + 5, k + 17, Blocks.air);
		world.setBlock(i + 10, j + 5, k + 18, Blocks.air);
		world.setBlock(i + 10, j + 5, k + 19, Blocks.air);
		world.setBlock(i + 10, j + 5, k + 20, Blocks.air);
		world.setBlock(i + 10, j + 5, k + 21, Blocks.air);
		world.setBlock(i + 10, j + 5, k + 22, Blocks.air);
		world.setBlock(i + 10, j + 5, k + 23, Blocks.air);
		world.setBlock(i + 10, j + 6, k + 12, Blocks.fire);
		world.setBlock(i + 10, j + 6, k + 13, Blocks.air);
		world.setBlock(i + 10, j + 6, k + 14, Blocks.air);
		world.setBlock(i + 10, j + 6, k + 15, Blocks.air);
		world.setBlock(i + 10, j + 6, k + 16, Blocks.air);
		world.setBlock(i + 10, j + 6, k + 17, Blocks.air);
		world.setBlock(i + 10, j + 6, k + 18, Blocks.air);
		world.setBlock(i + 10, j + 6, k + 19, Blocks.air);
		world.setBlock(i + 10, j + 6, k + 20, Blocks.air);
		world.setBlock(i + 10, j + 6, k + 21, Blocks.air);
		world.setBlock(i + 10, j + 6, k + 22, Blocks.air);
		world.setBlock(i + 10, j + 7, k + 13, Blocks.fire);
		world.setBlock(i + 10, j + 7, k + 15, Blocks.air);
		world.setBlock(i + 10, j + 7, k + 16, Blocks.air);
		world.setBlock(i + 10, j + 7, k + 17, Blocks.air);
		world.setBlock(i + 10, j + 7, k + 18, Blocks.air);
		world.setBlock(i + 10, j + 7, k + 19, Blocks.air);
		world.setBlock(i + 10, j + 7, k + 20, Blocks.air);
		world.setBlock(i + 10, j + 7, k + 21, Blocks.fire);
		world.setBlock(i + 10, j + 8, k + 17, Blocks.fire);
		world.setBlock(i + 10, j + 8, k + 18, Blocks.fire);
		world.setBlock(i + 11, j + 0, k + 1, this.topType());
		world.setBlock(i + 11, j + 0, k + 2, this.landType());
		world.setBlock(i + 11, j + 0, k + 3, this.landType());
		world.setBlock(i + 11, j + 0, k + 4, this.landType());
		world.setBlock(i + 11, j + 0, k + 5, this.landType());
		world.setBlock(i + 11, j + 0, k + 6, this.landType());
		world.setBlock(i + 11, j + 0, k + 7, this.landType());
		world.setBlock(i + 11, j + 0, k + 8, this.landType());
		world.setBlock(i + 11, j + 0, k + 9, this.landType());
		world.setBlock(i + 11, j + 0, k + 10, this.landType());
		world.setBlock(i + 11, j + 0, k + 11, this.landType());
		world.setBlock(i + 11, j + 0, k + 12, this.landType());
		world.setBlock(i + 11, j + 0, k + 13, this.landType());
		world.setBlock(i + 11, j + 0, k + 14, this.landType());
		world.setBlock(i + 11, j + 0, k + 15, this.landType());
		world.setBlock(i + 11, j + 0, k + 16, this.landType());
		world.setBlock(i + 11, j + 0, k + 17, this.landType());
		world.setBlock(i + 11, j + 0, k + 18, this.landType());
		world.setBlock(i + 11, j + 0, k + 19, this.landType());
		world.setBlock(i + 11, j + 0, k + 20, this.landType());
		world.setBlock(i + 11, j + 0, k + 21, this.landType());
		world.setBlock(i + 11, j + 0, k + 22, this.landType());
		world.setBlock(i + 11, j + 0, k + 23, this.landType());
		world.setBlock(i + 11, j + 0, k + 24, this.landType());
		world.setBlock(i + 11, j + 0, k + 25, this.landType());
		world.setBlock(i + 11, j + 0, k + 26, this.landType());
		world.setBlock(i + 11, j + 0, k + 27, this.landType());
		world.setBlock(i + 11, j + 0, k + 28, this.landType());
		world.setBlock(i + 11, j + 0, k + 29, this.landType());
		world.setBlock(i + 11, j + 0, k + 30, this.landType());
		world.setBlock(i + 11, j + 0, k + 31, this.landType());
		world.setBlock(i + 11, j + 0, k + 32, this.landType());
		world.setBlock(i + 11, j + 0, k + 33, this.topType());
		world.setBlock(i + 11, j + 1, k + 2, this.topType());
		world.setBlock(i + 11, j + 1, k + 3, this.landType());
		world.setBlock(i + 11, j + 1, k + 4, this.landType());
		world.setBlock(i + 11, j + 1, k + 5, this.landType());
		world.setBlock(i + 11, j + 1, k + 6, this.landType());
		world.setBlock(i + 11, j + 1, k + 7, this.landType());
		world.setBlock(i + 11, j + 1, k + 8, this.landType());
		world.setBlock(i + 11, j + 1, k + 9, this.landType());
		world.setBlock(i + 11, j + 1, k + 10, this.landType());
		world.setBlock(i + 11, j + 1, k + 11, this.landType());
		world.setBlock(i + 11, j + 1, k + 12, this.landType());
		world.setBlock(i + 11, j + 1, k + 13, this.landType());
		world.setBlock(i + 11, j + 1, k + 14, this.landType());
		world.setBlock(i + 11, j + 1, k + 15, Blocks.double_stone_slab);
		world.setBlock(i + 11, j + 1, k + 16, Blocks.double_stone_slab);
		world.setBlock(i + 11, j + 1, k + 17, Blocks.double_stone_slab);
		world.setBlock(i + 11, j + 1, k + 18, Blocks.double_stone_slab);
		world.setBlock(i + 11, j + 1, k + 19, Blocks.double_stone_slab);
		world.setBlock(i + 11, j + 1, k + 20, this.landType());
		world.setBlock(i + 11, j + 1, k + 21, this.landType());
		world.setBlock(i + 11, j + 1, k + 22, this.landType());
		world.setBlock(i + 11, j + 1, k + 23, this.landType());
		world.setBlock(i + 11, j + 1, k + 24, this.landType());
		world.setBlock(i + 11, j + 1, k + 25, this.landType());
		world.setBlock(i + 11, j + 1, k + 26, this.landType());
		world.setBlock(i + 11, j + 1, k + 27, this.landType());
		world.setBlock(i + 11, j + 1, k + 28, this.landType());
		world.setBlock(i + 11, j + 1, k + 29, this.landType());
		world.setBlock(i + 11, j + 1, k + 30, this.landType());
		world.setBlock(i + 11, j + 1, k + 31, this.landType());
		world.setBlock(i + 11, j + 1, k + 32, this.topType());
		world.setBlock(i + 11, j + 2, k + 3, this.topType());
		world.setBlock(i + 11, j + 2, k + 4, this.topType());
		world.setBlock(i + 11, j + 2, k + 5, this.topType());
		world.setBlock(i + 11, j + 2, k + 6, this.topType());
		world.setBlock(i + 11, j + 2, k + 7, this.topType());
		world.setBlock(i + 11, j + 2, k + 8, this.topType());
		world.setBlock(i + 11, j + 2, k + 9, this.topType());
		world.setBlock(i + 11, j + 2, k + 10, this.topType());
		world.setBlock(i + 11, j + 2, k + 11, this.topType());
		world.setBlock(i + 11, j + 2, k + 12, this.topType());
		world.setBlock(i + 11, j + 2, k + 13, this.topType());
		world.setBlock(i + 11, j + 2, k + 14, this.topType());
		world.setBlock(i + 11, j + 2, k + 15, Blocks.double_stone_slab);
		world.setBlock(i + 11, j + 2, k + 16, Blocks.air);
		world.setBlock(i + 11, j + 2, k + 17, HalocraftBlocks.MetalLadder);
		world.setBlockMetadataWithNotify(i + 11, j + 2, k + 17, 5, 3); 
		world.setBlock(i + 11, j + 2, k + 18, HalocraftBlocks.MetalLadder);
		world.setBlockMetadataWithNotify(i + 11, j + 2, k + 18, 5, 3); 
		world.setBlock(i + 11, j + 2, k + 19, Blocks.double_stone_slab);
		world.setBlock(i + 11, j + 2, k + 20, this.topType());
		world.setBlock(i + 11, j + 2, k + 21, this.topType());
		world.setBlock(i + 11, j + 2, k + 22, this.topType());
		world.setBlock(i + 11, j + 2, k + 23, this.topType());
		world.setBlock(i + 11, j + 2, k + 24, this.topType());
		world.setBlock(i + 11, j + 2, k + 25, this.topType());
		world.setBlock(i + 11, j + 2, k + 26, this.topType());
		world.setBlock(i + 11, j + 2, k + 27, this.topType());
		world.setBlock(i + 11, j + 2, k + 28, this.topType());
		world.setBlock(i + 11, j + 2, k + 29, this.topType());
		world.setBlock(i + 11, j + 2, k + 30, this.topType());
		world.setBlock(i + 11, j + 2, k + 31, this.topType());
		world.setBlock(i + 11, j + 3, k + 6, this.landType());
		world.setBlock(i + 11, j + 3, k + 10, this.landType());
		world.setBlock(i + 11, j + 3, k + 11, this.landType());
		world.setBlock(i + 11, j + 3, k + 12, this.landType());
		world.setBlock(i + 11, j + 3, k + 13, this.landType());
		world.setBlock(i + 11, j + 3, k + 14, Blocks.double_stone_slab);
		world.setBlock(i + 11, j + 3, k + 15, Blocks.double_stone_slab);
		world.setBlock(i + 11, j + 3, k + 16, Blocks.air);
		world.setBlock(i + 11, j + 3, k + 17, Blocks.air);
		world.setBlock(i + 11, j + 3, k + 18, Blocks.air);
		world.setBlock(i + 11, j + 3, k + 19, Blocks.double_stone_slab);
		world.setBlock(i + 11, j + 3, k + 20, Blocks.double_stone_slab);
		world.setBlock(i + 11, j + 3, k + 21, this.landType());
		world.setBlock(i + 11, j + 3, k + 22, this.landType());
		world.setBlock(i + 11, j + 3, k + 23, this.landType());
		world.setBlock(i + 11, j + 3, k + 24, this.landType());
		world.setBlock(i + 11, j + 3, k + 25, this.landType());
		world.setBlock(i + 11, j + 4, k + 6, Blocks.fire);
		world.setBlock(i + 11, j + 4, k + 10, Blocks.air);
		world.setBlock(i + 11, j + 4, k + 11, this.landType());
		world.setBlock(i + 11, j + 4, k + 12, this.landType());
		world.setBlock(i + 11, j + 4, k + 13, this.landType());
		world.setBlock(i + 11, j + 4, k + 14, Blocks.air);
		world.setBlock(i + 11, j + 4, k + 15, Blocks.stone_slab);
		world.setBlock(i + 11, j + 4, k + 16, Blocks.stone_slab);
		world.setBlockMetadataWithNotify(i + 11, j + 4, k + 16, 8, 3); 
		world.setBlock(i + 11, j + 4, k + 17, Blocks.stone_slab);
		world.setBlockMetadataWithNotify(i + 11, j + 4, k + 17, 8, 3); 
		world.setBlock(i + 11, j + 4, k + 18, Blocks.stone_slab);
		world.setBlockMetadataWithNotify(i + 11, j + 4, k + 18, 8, 3); 
		world.setBlock(i + 11, j + 4, k + 19, Blocks.stone_slab);
		world.setBlock(i + 11, j + 4, k + 20, Blocks.air);
		world.setBlock(i + 11, j + 4, k + 21, this.landType());
		world.setBlock(i + 11, j + 4, k + 22, this.landType());
		world.setBlock(i + 11, j + 4, k + 23, this.landType());
		world.setBlock(i + 11, j + 4, k + 24, Blocks.air);
		world.setBlock(i + 11, j + 4, k + 25, Blocks.air);
		world.setBlock(i + 11, j + 5, k + 10, Blocks.fire);
		world.setBlock(i + 11, j + 5, k + 11, Blocks.air);
		world.setBlock(i + 11, j + 5, k + 12, Blocks.air);
		world.setBlock(i + 11, j + 5, k + 13, Blocks.air);
		world.setBlock(i + 11, j + 5, k + 14, Blocks.air);
		world.setBlock(i + 11, j + 5, k + 15, Blocks.air);
		world.setBlock(i + 11, j + 5, k + 16, Blocks.air);
		world.setBlock(i + 11, j + 5, k + 17, Blocks.air);
		world.setBlock(i + 11, j + 5, k + 18, Blocks.air);
		world.setBlock(i + 11, j + 5, k + 19, Blocks.air);
		world.setBlock(i + 11, j + 5, k + 20, Blocks.air);
		world.setBlock(i + 11, j + 5, k + 21, Blocks.air);
		world.setBlock(i + 11, j + 5, k + 22, this.landType());
		world.setBlock(i + 11, j + 5, k + 23, Blocks.fire);
		world.setBlock(i + 11, j + 5, k + 24, Blocks.air);
		world.setBlock(i + 11, j + 6, k + 11, Blocks.fire);
		world.setBlock(i + 11, j + 6, k + 12, Blocks.air);
		world.setBlock(i + 11, j + 6, k + 13, Blocks.air);
		world.setBlock(i + 11, j + 6, k + 14, Blocks.air);
		world.setBlock(i + 11, j + 6, k + 15, Blocks.air);
		world.setBlock(i + 11, j + 6, k + 16, Blocks.air);
		world.setBlock(i + 11, j + 6, k + 17, Blocks.air);
		world.setBlock(i + 11, j + 6, k + 18, Blocks.air);
		world.setBlock(i + 11, j + 6, k + 19, Blocks.air);
		world.setBlock(i + 11, j + 6, k + 20, Blocks.air);
		world.setBlock(i + 11, j + 6, k + 21, Blocks.air);
		world.setBlock(i + 11, j + 6, k + 22, Blocks.air);
		world.setBlock(i + 11, j + 6, k + 23, Blocks.air);
		world.setBlock(i + 11, j + 6, k + 24, Blocks.fire);
		world.setBlock(i + 11, j + 7, k + 14, Blocks.air);
		world.setBlock(i + 11, j + 7, k + 15, Blocks.air);
		world.setBlock(i + 11, j + 7, k + 16, Blocks.air);
		world.setBlock(i + 11, j + 7, k + 17, Blocks.air);
		world.setBlock(i + 11, j + 7, k + 18, Blocks.air);
		world.setBlock(i + 11, j + 7, k + 19, Blocks.air);
		world.setBlock(i + 11, j + 7, k + 20, Blocks.air);
		world.setBlock(i + 11, j + 7, k + 21, Blocks.air);
		world.setBlock(i + 11, j + 7, k + 22, Blocks.fire);
		world.setBlock(i + 11, j + 8, k + 14, Blocks.fire);
		world.setBlock(i + 11, j + 8, k + 15, Blocks.fire);
		world.setBlock(i + 11, j + 8, k + 16, Blocks.air);
		world.setBlock(i + 11, j + 8, k + 17, Blocks.air);
		world.setBlock(i + 11, j + 8, k + 18, Blocks.air);
		world.setBlock(i + 11, j + 8, k + 19, Blocks.air);
		world.setBlock(i + 11, j + 8, k + 20, Blocks.fire);
		world.setBlock(i + 11, j + 9, k + 16, Blocks.fire);
		world.setBlock(i + 11, j + 9, k + 18, Blocks.fire);
		world.setBlock(i + 12, j + 0, k + 0, this.topType());
		world.setBlock(i + 12, j + 0, k + 1, this.landType());
		world.setBlock(i + 12, j + 0, k + 2, this.landType());
		world.setBlock(i + 12, j + 0, k + 3, this.landType());
		world.setBlock(i + 12, j + 0, k + 4, this.landType());
		world.setBlock(i + 12, j + 0, k + 5, this.landType());
		world.setBlock(i + 12, j + 0, k + 6, this.landType());
		world.setBlock(i + 12, j + 0, k + 7, this.landType());
		world.setBlock(i + 12, j + 0, k + 8, this.landType());
		world.setBlock(i + 12, j + 0, k + 9, this.landType());
		world.setBlock(i + 12, j + 0, k + 10, this.landType());
		world.setBlock(i + 12, j + 0, k + 11, this.landType());
		world.setBlock(i + 12, j + 0, k + 12, this.landType());
		world.setBlock(i + 12, j + 0, k + 13, this.landType());
		world.setBlock(i + 12, j + 0, k + 14, this.landType());
		world.setBlock(i + 12, j + 0, k + 15, this.landType());
		world.setBlock(i + 12, j + 0, k + 16, this.landType());
		world.setBlock(i + 12, j + 0, k + 17, this.landType());
		world.setBlock(i + 12, j + 0, k + 18, this.landType());
		world.setBlock(i + 12, j + 0, k + 19, this.landType());
		world.setBlock(i + 12, j + 0, k + 20, this.landType());
		world.setBlock(i + 12, j + 0, k + 21, this.landType());
		world.setBlock(i + 12, j + 0, k + 22, this.landType());
		world.setBlock(i + 12, j + 0, k + 23, this.landType());
		world.setBlock(i + 12, j + 0, k + 24, this.landType());
		world.setBlock(i + 12, j + 0, k + 25, this.landType());
		world.setBlock(i + 12, j + 0, k + 26, this.landType());
		world.setBlock(i + 12, j + 0, k + 27, this.landType());
		world.setBlock(i + 12, j + 0, k + 28, this.landType());
		world.setBlock(i + 12, j + 0, k + 29, this.landType());
		world.setBlock(i + 12, j + 0, k + 30, this.landType());
		world.setBlock(i + 12, j + 0, k + 31, this.landType());
		world.setBlock(i + 12, j + 0, k + 32, this.landType());
		world.setBlock(i + 12, j + 0, k + 33, this.landType());
		world.setBlock(i + 12, j + 0, k + 34, this.topType());
		world.setBlock(i + 12, j + 1, k + 1, this.topType());
		world.setBlock(i + 12, j + 1, k + 2, this.landType());
		world.setBlock(i + 12, j + 1, k + 3, this.landType());
		world.setBlock(i + 12, j + 1, k + 4, this.landType());
		world.setBlock(i + 12, j + 1, k + 5, this.landType());
		world.setBlock(i + 12, j + 1, k + 6, this.landType());
		world.setBlock(i + 12, j + 1, k + 7, this.landType());
		world.setBlock(i + 12, j + 1, k + 8, this.landType());
		world.setBlock(i + 12, j + 1, k + 9, this.landType());
		world.setBlock(i + 12, j + 1, k + 10, this.landType());
		world.setBlock(i + 12, j + 1, k + 11, this.landType());
		world.setBlock(i + 12, j + 1, k + 12, this.landType());
		world.setBlock(i + 12, j + 1, k + 13, this.landType());
		world.setBlock(i + 12, j + 1, k + 14, this.landType());
		world.setBlock(i + 12, j + 1, k + 15, Blocks.double_stone_slab);
		world.setBlock(i + 12, j + 1, k + 16, Blocks.double_stone_slab);
		world.setBlock(i + 12, j + 1, k + 17, Blocks.double_stone_slab);
		world.setBlock(i + 12, j + 1, k + 18, Blocks.double_stone_slab);
		world.setBlock(i + 12, j + 1, k + 19, Blocks.double_stone_slab);
		world.setBlock(i + 12, j + 1, k + 20, this.landType());
		world.setBlock(i + 12, j + 1, k + 21, this.landType());
		world.setBlock(i + 12, j + 1, k + 22, this.landType());
		world.setBlock(i + 12, j + 1, k + 23, this.landType());
		world.setBlock(i + 12, j + 1, k + 24, this.landType());
		world.setBlock(i + 12, j + 1, k + 25, this.landType());
		world.setBlock(i + 12, j + 1, k + 26, this.landType());
		world.setBlock(i + 12, j + 1, k + 27, this.landType());
		world.setBlock(i + 12, j + 1, k + 28, this.landType());
		world.setBlock(i + 12, j + 1, k + 29, this.landType());
		world.setBlock(i + 12, j + 1, k + 30, this.landType());
		world.setBlock(i + 12, j + 1, k + 31, this.landType());
		world.setBlock(i + 12, j + 1, k + 32, this.landType());
		world.setBlock(i + 12, j + 1, k + 33, this.topType());
		world.setBlock(i + 12, j + 2, k + 2, this.topType());
		world.setBlock(i + 12, j + 2, k + 3, this.topType());
		world.setBlock(i + 12, j + 2, k + 4, this.topType());
		world.setBlock(i + 12, j + 2, k + 5, this.topType());
		world.setBlock(i + 12, j + 2, k + 6, this.topType());
		world.setBlock(i + 12, j + 2, k + 7, this.topType());
		world.setBlock(i + 12, j + 2, k + 8, this.topType());
		world.setBlock(i + 12, j + 2, k + 9, this.topType());
		world.setBlock(i + 12, j + 2, k + 10, this.topType());
		world.setBlock(i + 12, j + 2, k + 11, this.topType());
		world.setBlock(i + 12, j + 2, k + 12, this.topType());
		world.setBlock(i + 12, j + 2, k + 13, this.topType());
		world.setBlock(i + 12, j + 2, k + 14, this.topType());
		world.setBlock(i + 12, j + 2, k + 15, Blocks.double_stone_slab);
		world.setBlock(i + 12, j + 2, k + 16, Blocks.air);
		world.setBlock(i + 12, j + 2, k + 17, Blocks.stone_brick_stairs);
		world.setBlock(i + 12, j + 2, k + 18, Blocks.stone_brick_stairs);
		world.setBlock(i + 12, j + 2, k + 19, Blocks.double_stone_slab);
		world.setBlock(i + 12, j + 2, k + 20, this.topType());
		world.setBlock(i + 12, j + 2, k + 21, this.topType());
		world.setBlock(i + 12, j + 2, k + 22, this.topType());
		world.setBlock(i + 12, j + 2, k + 23, this.topType());
		world.setBlock(i + 12, j + 2, k + 24, this.topType());
		world.setBlock(i + 12, j + 2, k + 25, this.topType());
		world.setBlock(i + 12, j + 2, k + 26, this.topType());
		world.setBlock(i + 12, j + 2, k + 27, this.topType());
		world.setBlock(i + 12, j + 2, k + 28, this.topType());
		world.setBlock(i + 12, j + 2, k + 29, this.topType());
		world.setBlock(i + 12, j + 2, k + 30, this.topType());
		world.setBlock(i + 12, j + 2, k + 31, this.topType());
		world.setBlock(i + 12, j + 2, k + 32, this.topType());
		world.setBlock(i + 12, j + 3, k + 10, this.landType());
		world.setBlock(i + 12, j + 3, k + 11, this.landType());
		world.setBlock(i + 12, j + 3, k + 12, this.landType());
		world.setBlock(i + 12, j + 3, k + 13, this.landType());
		world.setBlock(i + 12, j + 3, k + 14, Blocks.double_stone_slab);
		world.setBlock(i + 12, j + 3, k + 15, Blocks.double_stone_slab);
		world.setBlock(i + 12, j + 3, k + 16, Blocks.air);
		world.setBlock(i + 12, j + 3, k + 17, Blocks.air);
		world.setBlock(i + 12, j + 3, k + 18, Blocks.air);
		world.setBlock(i + 12, j + 3, k + 19, Blocks.double_stone_slab);
		world.setBlock(i + 12, j + 3, k + 20, Blocks.double_stone_slab);
		world.setBlock(i + 12, j + 3, k + 21, this.landType());
		world.setBlock(i + 12, j + 3, k + 22, this.landType());
		world.setBlock(i + 12, j + 3, k + 23, this.landType());
		world.setBlock(i + 12, j + 3, k + 24, this.landType());
		world.setBlock(i + 12, j + 3, k + 25, this.landType());
		world.setBlock(i + 12, j + 3, k + 26, this.landType());
		world.setBlock(i + 12, j + 3, k + 29, this.landType());
		world.setBlock(i + 12, j + 4, k + 10, Blocks.air);
		world.setBlock(i + 12, j + 4, k + 11, this.landType());
		world.setBlock(i + 12, j + 4, k + 12, this.landType());
		world.setBlock(i + 12, j + 4, k + 13, this.landType());
		world.setBlock(i + 12, j + 4, k + 14, Blocks.stone_slab);
		world.setBlock(i + 12, j + 4, k + 15, Blocks.double_stone_slab);
		world.setBlock(i + 12, j + 4, k + 16, Blocks.stone_slab);
		world.setBlockMetadataWithNotify(i + 12, j + 4, k + 16, 8, 3); 
		world.setBlock(i + 12, j + 4, k + 17, Blocks.stone_slab);
		world.setBlockMetadataWithNotify(i + 12, j + 4, k + 17, 8, 3); 
		world.setBlock(i + 12, j + 4, k + 18, Blocks.stone_slab);
		world.setBlockMetadataWithNotify(i + 12, j + 4, k + 18, 8, 3); 
		world.setBlock(i + 12, j + 4, k + 19, Blocks.double_stone_slab);
		world.setBlock(i + 12, j + 4, k + 20, Blocks.stone_slab);
		world.setBlock(i + 12, j + 4, k + 21, this.landType());
		world.setBlock(i + 12, j + 4, k + 22, this.landType());
		world.setBlock(i + 12, j + 4, k + 23, this.landType());
		world.setBlock(i + 12, j + 4, k + 24, this.landType());
		world.setBlock(i + 12, j + 4, k + 25, Blocks.air);
		world.setBlock(i + 12, j + 4, k + 26, Blocks.air);
		world.setBlock(i + 12, j + 4, k + 29, Blocks.fire);
		world.setBlock(i + 12, j + 5, k + 11, Blocks.air);
		world.setBlock(i + 12, j + 5, k + 12, Blocks.air);
		world.setBlock(i + 12, j + 5, k + 13, Blocks.air);
		world.setBlock(i + 12, j + 5, k + 14, Blocks.air);
		world.setBlock(i + 12, j + 5, k + 15, Blocks.air);
		world.setBlock(i + 12, j + 5, k + 16, Blocks.stone_slab);
		world.setBlock(i + 12, j + 5, k + 17, Blocks.stone_slab);
		world.setBlock(i + 12, j + 5, k + 18, Blocks.stone_slab);
		world.setBlock(i + 12, j + 5, k + 19, Blocks.air);
		world.setBlock(i + 12, j + 5, k + 20, Blocks.air);
		world.setBlock(i + 12, j + 5, k + 21, Blocks.air);
		world.setBlock(i + 12, j + 5, k + 22, this.landType());
		world.setBlock(i + 12, j + 5, k + 23, this.landType());
		world.setBlock(i + 12, j + 5, k + 24, Blocks.air);
		world.setBlock(i + 12, j + 5, k + 25, Blocks.fire);
		world.setBlock(i + 12, j + 6, k + 12, Blocks.air);
		world.setBlock(i + 12, j + 6, k + 13, Blocks.air);
		world.setBlock(i + 12, j + 6, k + 14, Blocks.air);
		world.setBlock(i + 12, j + 6, k + 15, Blocks.air);
		world.setBlock(i + 12, j + 6, k + 16, Blocks.air);
		world.setBlock(i + 12, j + 6, k + 17, Blocks.air);
		world.setBlock(i + 12, j + 6, k + 18, Blocks.air);
		world.setBlock(i + 12, j + 6, k + 19, Blocks.air);
		world.setBlock(i + 12, j + 6, k + 20, Blocks.air);
		world.setBlock(i + 12, j + 6, k + 21, Blocks.air);
		world.setBlock(i + 12, j + 6, k + 22, Blocks.air);
		world.setBlock(i + 12, j + 6, k + 23, Blocks.air);
		world.setBlock(i + 12, j + 7, k + 12, Blocks.fire);
		world.setBlock(i + 12, j + 7, k + 13, Blocks.air);
		world.setBlock(i + 12, j + 7, k + 14, Blocks.air);
		world.setBlock(i + 12, j + 7, k + 15, Blocks.air);
		world.setBlock(i + 12, j + 7, k + 16, Blocks.air);
		world.setBlock(i + 12, j + 7, k + 17, Blocks.air);
		world.setBlock(i + 12, j + 7, k + 18, Blocks.air);
		world.setBlock(i + 12, j + 7, k + 19, Blocks.air);
		world.setBlock(i + 12, j + 7, k + 20, Blocks.air);
		world.setBlock(i + 12, j + 7, k + 21, Blocks.air);
		world.setBlock(i + 12, j + 7, k + 22, Blocks.air);
		world.setBlock(i + 12, j + 7, k + 23, Blocks.fire);
		world.setBlock(i + 12, j + 8, k + 14, Blocks.fire);
		world.setBlock(i + 12, j + 8, k + 15, Blocks.air);
		world.setBlock(i + 12, j + 8, k + 16, Blocks.air);
		world.setBlock(i + 12, j + 8, k + 17, Blocks.air);
		world.setBlock(i + 12, j + 8, k + 18, Blocks.air);
		world.setBlock(i + 12, j + 8, k + 19, Blocks.air);
		world.setBlock(i + 12, j + 8, k + 20, Blocks.air);
		world.setBlock(i + 12, j + 8, k + 21, Blocks.fire);
		world.setBlock(i + 12, j + 9, k + 16, Blocks.air);
		world.setBlock(i + 12, j + 9, k + 17, Blocks.air);
		world.setBlock(i + 12, j + 9, k + 18, Blocks.air);
		world.setBlock(i + 12, j + 9, k + 19, Blocks.fire);
		world.setBlock(i + 12, j + 10, k + 17, Blocks.fire);
		world.setBlock(i + 13, j + 0, k + 0, this.topType());
		world.setBlock(i + 13, j + 0, k + 1, this.landType());
		world.setBlock(i + 13, j + 0, k + 2, this.landType());
		world.setBlock(i + 13, j + 0, k + 3, this.landType());
		world.setBlock(i + 13, j + 0, k + 4, this.landType());
		world.setBlock(i + 13, j + 0, k + 5, this.landType());
		world.setBlock(i + 13, j + 0, k + 6, this.landType());
		world.setBlock(i + 13, j + 0, k + 7, this.landType());
		world.setBlock(i + 13, j + 0, k + 8, this.landType());
		world.setBlock(i + 13, j + 0, k + 9, this.landType());
		world.setBlock(i + 13, j + 0, k + 10, this.landType());
		world.setBlock(i + 13, j + 0, k + 11, this.landType());
		world.setBlock(i + 13, j + 0, k + 12, this.landType());
		world.setBlock(i + 13, j + 0, k + 13, this.landType());
		world.setBlock(i + 13, j + 0, k + 14, this.landType());
		world.setBlock(i + 13, j + 0, k + 15, this.landType());
		world.setBlock(i + 13, j + 0, k + 16, this.landType());
		world.setBlock(i + 13, j + 0, k + 17, this.landType());
		world.setBlock(i + 13, j + 0, k + 18, this.landType());
		world.setBlock(i + 13, j + 0, k + 19, this.landType());
		world.setBlock(i + 13, j + 0, k + 20, this.landType());
		world.setBlock(i + 13, j + 0, k + 21, this.landType());
		world.setBlock(i + 13, j + 0, k + 22, this.landType());
		world.setBlock(i + 13, j + 0, k + 23, this.landType());
		world.setBlock(i + 13, j + 0, k + 24, this.landType());
		world.setBlock(i + 13, j + 0, k + 25, this.landType());
		world.setBlock(i + 13, j + 0, k + 26, this.landType());
		world.setBlock(i + 13, j + 0, k + 27, this.landType());
		world.setBlock(i + 13, j + 0, k + 28, this.landType());
		world.setBlock(i + 13, j + 0, k + 29, this.landType());
		world.setBlock(i + 13, j + 0, k + 30, this.landType());
		world.setBlock(i + 13, j + 0, k + 31, this.landType());
		world.setBlock(i + 13, j + 0, k + 32, this.landType());
		world.setBlock(i + 13, j + 0, k + 33, this.landType());
		world.setBlock(i + 13, j + 0, k + 34, this.topType());
		world.setBlock(i + 13, j + 1, k + 1, this.topType());
		world.setBlock(i + 13, j + 1, k + 2, this.landType());
		world.setBlock(i + 13, j + 1, k + 3, this.landType());
		world.setBlock(i + 13, j + 1, k + 4, this.landType());
		world.setBlock(i + 13, j + 1, k + 5, this.landType());
		world.setBlock(i + 13, j + 1, k + 6, this.landType());
		world.setBlock(i + 13, j + 1, k + 7, this.landType());
		world.setBlock(i + 13, j + 1, k + 8, this.landType());
		world.setBlock(i + 13, j + 1, k + 9, this.landType());
		world.setBlock(i + 13, j + 1, k + 10, this.landType());
		world.setBlock(i + 13, j + 1, k + 11, this.landType());
		world.setBlock(i + 13, j + 1, k + 12, this.landType());
		world.setBlock(i + 13, j + 1, k + 13, this.landType());
		world.setBlock(i + 13, j + 1, k + 14, this.landType());
		world.setBlock(i + 13, j + 1, k + 15, Blocks.double_stone_slab);
		world.setBlock(i + 13, j + 1, k + 16, Blocks.double_stone_slab);
		world.setBlock(i + 13, j + 1, k + 17, Blocks.double_stone_slab);
		world.setBlock(i + 13, j + 1, k + 18, Blocks.double_stone_slab);
		world.setBlock(i + 13, j + 1, k + 19, Blocks.double_stone_slab);
		world.setBlock(i + 13, j + 1, k + 20, this.landType());
		world.setBlock(i + 13, j + 1, k + 21, this.landType());
		world.setBlock(i + 13, j + 1, k + 22, this.landType());
		world.setBlock(i + 13, j + 1, k + 23, this.landType());
		world.setBlock(i + 13, j + 1, k + 24, this.landType());
		world.setBlock(i + 13, j + 1, k + 25, this.landType());
		world.setBlock(i + 13, j + 1, k + 26, this.landType());
		world.setBlock(i + 13, j + 1, k + 27, this.landType());
		world.setBlock(i + 13, j + 1, k + 28, this.landType());
		world.setBlock(i + 13, j + 1, k + 29, this.landType());
		world.setBlock(i + 13, j + 1, k + 30, this.landType());
		world.setBlock(i + 13, j + 1, k + 31, this.landType());
		world.setBlock(i + 13, j + 1, k + 32, this.landType());
		world.setBlock(i + 13, j + 1, k + 33, this.topType());
		world.setBlock(i + 13, j + 2, k + 2, this.topType());
		world.setBlock(i + 13, j + 2, k + 3, this.topType());
		world.setBlock(i + 13, j + 2, k + 4, this.topType());
		world.setBlock(i + 13, j + 2, k + 5, this.topType());
		world.setBlock(i + 13, j + 2, k + 6, this.topType());
		world.setBlock(i + 13, j + 2, k + 7, this.topType());
		world.setBlock(i + 13, j + 2, k + 8, this.topType());
		world.setBlock(i + 13, j + 2, k + 9, this.topType());
		world.setBlock(i + 13, j + 2, k + 10, this.topType());
		world.setBlock(i + 13, j + 2, k + 11, this.topType());
		world.setBlock(i + 13, j + 2, k + 12, this.topType());
		world.setBlock(i + 13, j + 2, k + 13, this.topType());
		world.setBlock(i + 13, j + 2, k + 14, this.topType());
		world.setBlock(i + 13, j + 2, k + 15, Blocks.double_stone_slab);
		world.setBlock(i + 13, j + 2, k + 16, Blocks.air);
		world.setBlock(i + 13, j + 2, k + 17, Blocks.double_stone_slab);
		world.setBlock(i + 13, j + 2, k + 18, Blocks.double_stone_slab);
		world.setBlock(i + 13, j + 2, k + 19, Blocks.double_stone_slab);
		world.setBlock(i + 13, j + 2, k + 20, this.topType());
		world.setBlock(i + 13, j + 2, k + 21, this.topType());
		world.setBlock(i + 13, j + 2, k + 22, this.topType());
		world.setBlock(i + 13, j + 2, k + 23, this.topType());
		world.setBlock(i + 13, j + 2, k + 24, this.topType());
		world.setBlock(i + 13, j + 2, k + 25, this.topType());
		world.setBlock(i + 13, j + 2, k + 26, this.topType());
		world.setBlock(i + 13, j + 2, k + 27, this.topType());
		world.setBlock(i + 13, j + 2, k + 28, this.topType());
		world.setBlock(i + 13, j + 2, k + 29, this.topType());
		world.setBlock(i + 13, j + 2, k + 30, this.topType());
		world.setBlock(i + 13, j + 2, k + 31, this.topType());
		world.setBlock(i + 13, j + 2, k + 32, this.topType());
		world.setBlock(i + 13, j + 3, k + 4, this.landType());
		world.setBlock(i + 13, j + 3, k + 6, Blocks.fire);
		world.setBlock(i + 13, j + 3, k + 9, this.landType());
		world.setBlock(i + 13, j + 3, k + 10, this.landType());
		world.setBlock(i + 13, j + 3, k + 11, this.landType());
		world.setBlock(i + 13, j + 3, k + 12, this.landType());
		world.setBlock(i + 13, j + 3, k + 13, this.landType());
		world.setBlock(i + 13, j + 3, k + 14, Blocks.double_stone_slab);
		world.setBlock(i + 13, j + 3, k + 15, Blocks.double_stone_slab);
		world.setBlock(i + 13, j + 3, k + 16, Blocks.air);
		world.setBlock(i + 13, j + 3, k + 17, Blocks.double_stone_slab);
		world.setBlock(i + 13, j + 3, k + 18, Blocks.double_stone_slab);
		world.setBlock(i + 13, j + 3, k + 19, Blocks.double_stone_slab);
		world.setBlock(i + 13, j + 3, k + 20, Blocks.double_stone_slab);
		world.setBlock(i + 13, j + 3, k + 21, this.landType());
		world.setBlock(i + 13, j + 3, k + 22, this.landType());
		world.setBlock(i + 13, j + 3, k + 23, this.landType());
		world.setBlock(i + 13, j + 3, k + 24, this.landType());
		world.setBlock(i + 13, j + 3, k + 25, this.landType());
		world.setBlock(i + 13, j + 3, k + 26, this.landType());
		world.setBlock(i + 13, j + 4, k + 4, Blocks.fire);
		world.setBlock(i + 13, j + 4, k + 9, Blocks.air);
		world.setBlock(i + 13, j + 4, k + 10, Blocks.air);
		world.setBlock(i + 13, j + 4, k + 11, this.landType());
		world.setBlock(i + 13, j + 4, k + 12, Blocks.double_stone_slab);
		world.setBlock(i + 13, j + 4, k + 13, this.landType());
		world.setBlock(i + 13, j + 4, k + 14, Blocks.double_stone_slab);
		world.setBlock(i + 13, j + 4, k + 15, Blocks.double_stone_slab);
		world.setBlock(i + 13, j + 4, k + 16, Blocks.double_stone_slab);
		world.setBlock(i + 13, j + 4, k + 17, Blocks.double_stone_slab);
		world.setBlock(i + 13, j + 4, k + 18, Blocks.double_stone_slab);
		world.setBlock(i + 13, j + 4, k + 19, Blocks.double_stone_slab);
		world.setBlock(i + 13, j + 4, k + 20, Blocks.double_stone_slab);
		world.setBlock(i + 13, j + 4, k + 21, this.landType());
		world.setBlock(i + 13, j + 4, k + 22, Blocks.double_stone_slab);
		world.setBlock(i + 13, j + 4, k + 23, this.landType());
		world.setBlock(i + 13, j + 4, k + 24, this.landType());
		world.setBlock(i + 13, j + 4, k + 25, this.landType());
		world.setBlock(i + 13, j + 4, k + 26, Blocks.air);
		world.setBlock(i + 13, j + 5, k + 10, Blocks.air);
		world.setBlock(i + 13, j + 5, k + 11, Blocks.air);
		world.setBlock(i + 13, j + 5, k + 12, Blocks.stone_brick_stairs);
		world.setBlock(i + 13, j + 5, k + 13, Blocks.air);
		world.setBlock(i + 13, j + 5, k + 14, Blocks.stone_slab);
		world.setBlock(i + 13, j + 5, k + 15, Blocks.stone_slab);
		world.setBlock(i + 13, j + 5, k + 16, Blocks.double_stone_slab);
		world.setBlock(i + 13, j + 5, k + 17, Blocks.double_stone_slab);
		world.setBlock(i + 13, j + 5, k + 18, Blocks.double_stone_slab);
		world.setBlock(i + 13, j + 5, k + 19, Blocks.stone_slab);
		world.setBlock(i + 13, j + 5, k + 20, Blocks.stone_slab);
		world.setBlock(i + 13, j + 5, k + 21, this.landType());
		world.setBlock(i + 13, j + 5, k + 22, this.landType());
		world.setBlock(i + 13, j + 5, k + 23, this.landType());
		world.setBlock(i + 13, j + 5, k + 24, this.landType());
		world.setBlock(i + 13, j + 5, k + 25, Blocks.air);
		world.setBlock(i + 13, j + 5, k + 26, Blocks.fire);
		world.setBlock(i + 13, j + 6, k + 10, Blocks.fire);
		world.setBlock(i + 13, j + 6, k + 11, Blocks.air);
		world.setBlock(i + 13, j + 6, k + 12, Blocks.air);
		world.setBlock(i + 13, j + 6, k + 13, Blocks.air);
		world.setBlock(i + 13, j + 6, k + 14, Blocks.air);
		world.setBlock(i + 13, j + 6, k + 15, Blocks.air);
		world.setBlock(i + 13, j + 6, k + 16, Blocks.air);
		world.setBlock(i + 13, j + 6, k + 17, Blocks.air);
		world.setBlock(i + 13, j + 6, k + 18, Blocks.air);
		world.setBlock(i + 13, j + 6, k + 19, Blocks.air);
		world.setBlock(i + 13, j + 6, k + 20, Blocks.air);
		world.setBlock(i + 13, j + 6, k + 21, Blocks.air);
		world.setBlock(i + 13, j + 6, k + 22, Blocks.air);
		world.setBlock(i + 13, j + 6, k + 23, Blocks.air);
		world.setBlock(i + 13, j + 6, k + 24, Blocks.fire);
		world.setBlock(i + 13, j + 7, k + 11, Blocks.fire);
		world.setBlock(i + 13, j + 7, k + 12, Blocks.air);
		world.setBlock(i + 13, j + 7, k + 13, Blocks.air);
		world.setBlock(i + 13, j + 7, k + 14, Blocks.air);
		world.setBlock(i + 13, j + 7, k + 15, Blocks.air);
		world.setBlock(i + 13, j + 7, k + 16, Blocks.air);
		world.setBlock(i + 13, j + 7, k + 17, Blocks.air);
		world.setBlock(i + 13, j + 7, k + 18, Blocks.air);
		world.setBlock(i + 13, j + 7, k + 19, Blocks.air);
		world.setBlock(i + 13, j + 7, k + 20, Blocks.air);
		world.setBlock(i + 13, j + 7, k + 21, Blocks.air);
		world.setBlock(i + 13, j + 7, k + 22, Blocks.air);
		world.setBlock(i + 13, j + 7, k + 23, Blocks.fire);
		world.setBlock(i + 13, j + 8, k + 13, Blocks.fire);
		world.setBlock(i + 13, j + 8, k + 14, Blocks.air);
		world.setBlock(i + 13, j + 8, k + 15, Blocks.air);
		world.setBlock(i + 13, j + 8, k + 16, Blocks.air);
		world.setBlock(i + 13, j + 8, k + 17, Blocks.air);
		world.setBlock(i + 13, j + 8, k + 18, Blocks.air);
		world.setBlock(i + 13, j + 8, k + 19, Blocks.air);
		world.setBlock(i + 13, j + 8, k + 20, Blocks.air);
		world.setBlock(i + 13, j + 8, k + 21, Blocks.air);
		world.setBlock(i + 13, j + 8, k + 22, Blocks.fire);
		world.setBlock(i + 13, j + 9, k + 14, Blocks.fire);
		world.setBlock(i + 13, j + 9, k + 15, Blocks.air);
		
		generate2(world, rand, i, j, k);
	}

	public void generate2(World world, Random rand, int i, int j, int k) {
		world.setBlock(i + 13, j + 9, k + 16, Blocks.air);
		world.setBlock(i + 13, j + 9, k + 17, Blocks.air);
		world.setBlock(i + 13, j + 9, k + 18, Blocks.air);
		world.setBlock(i + 13, j + 9, k + 19, Blocks.air);
		world.setBlock(i + 13, j + 9, k + 20, Blocks.fire);
		world.setBlock(i + 13, j + 10, k + 15, Blocks.fire);
		world.setBlock(i + 13, j + 10, k + 17, Blocks.air);
		world.setBlock(i + 13, j + 10, k + 18, Blocks.fire);
		world.setBlock(i + 14, j + 0, k + 0, this.topType());
		world.setBlock(i + 14, j + 0, k + 1, this.landType());
		world.setBlock(i + 14, j + 0, k + 2, this.landType());
		world.setBlock(i + 14, j + 0, k + 3, this.landType());
		world.setBlock(i + 14, j + 0, k + 4, this.landType());
		world.setBlock(i + 14, j + 0, k + 5, this.landType());
		world.setBlock(i + 14, j + 0, k + 6, this.landType());
		world.setBlock(i + 14, j + 0, k + 7, this.landType());
		world.setBlock(i + 14, j + 0, k + 8, this.landType());
		world.setBlock(i + 14, j + 0, k + 9, this.landType());
		world.setBlock(i + 14, j + 0, k + 10, this.landType());
		world.setBlock(i + 14, j + 0, k + 11, this.landType());
		world.setBlock(i + 14, j + 0, k + 12, this.landType());
		world.setBlock(i + 14, j + 0, k + 13, this.landType());
		world.setBlock(i + 14, j + 0, k + 14, this.landType());
		world.setBlock(i + 14, j + 0, k + 15, this.landType());
		world.setBlock(i + 14, j + 0, k + 16, this.landType());
		world.setBlock(i + 14, j + 0, k + 17, this.landType());
		world.setBlock(i + 14, j + 0, k + 18, this.landType());
		world.setBlock(i + 14, j + 0, k + 19, this.landType());
		world.setBlock(i + 14, j + 0, k + 20, this.landType());
		world.setBlock(i + 14, j + 0, k + 21, this.landType());
		world.setBlock(i + 14, j + 0, k + 22, this.landType());
		world.setBlock(i + 14, j + 0, k + 23, this.landType());
		world.setBlock(i + 14, j + 0, k + 24, this.landType());
		world.setBlock(i + 14, j + 0, k + 25, this.landType());
		world.setBlock(i + 14, j + 0, k + 26, this.landType());
		world.setBlock(i + 14, j + 0, k + 27, this.landType());
		world.setBlock(i + 14, j + 0, k + 28, this.landType());
		world.setBlock(i + 14, j + 0, k + 29, this.landType());
		world.setBlock(i + 14, j + 0, k + 30, this.landType());
		world.setBlock(i + 14, j + 0, k + 31, this.landType());
		world.setBlock(i + 14, j + 0, k + 32, this.landType());
		world.setBlock(i + 14, j + 0, k + 33, this.landType());
		world.setBlock(i + 14, j + 0, k + 34, this.topType());
		world.setBlock(i + 14, j + 1, k + 1, this.topType());
		world.setBlock(i + 14, j + 1, k + 2, this.landType());
		world.setBlock(i + 14, j + 1, k + 3, this.landType());
		world.setBlock(i + 14, j + 1, k + 4, this.landType());
		world.setBlock(i + 14, j + 1, k + 5, this.landType());
		world.setBlock(i + 14, j + 1, k + 6, this.landType());
		world.setBlock(i + 14, j + 1, k + 7, this.landType());
		world.setBlock(i + 14, j + 1, k + 8, this.landType());
		world.setBlock(i + 14, j + 1, k + 9, this.landType());
		world.setBlock(i + 14, j + 1, k + 10, this.landType());
		world.setBlock(i + 14, j + 1, k + 11, this.landType());
		world.setBlock(i + 14, j + 1, k + 12, this.landType());
		world.setBlock(i + 14, j + 1, k + 13, this.landType());
		world.setBlock(i + 14, j + 1, k + 14, this.landType());
		world.setBlock(i + 14, j + 1, k + 15, Blocks.double_stone_slab);
		world.setBlock(i + 14, j + 1, k + 16, Blocks.double_stone_slab);
		world.setBlock(i + 14, j + 1, k + 17, Blocks.double_stone_slab);
		world.setBlock(i + 14, j + 1, k + 19, Blocks.double_stone_slab);
		world.setBlock(i + 14, j + 1, k + 20, this.landType());
		world.setBlock(i + 14, j + 1, k + 21, this.landType());
		world.setBlock(i + 14, j + 1, k + 22, this.landType());
		world.setBlock(i + 14, j + 1, k + 23, this.landType());
		world.setBlock(i + 14, j + 1, k + 24, this.landType());
		world.setBlock(i + 14, j + 1, k + 25, this.landType());
		world.setBlock(i + 14, j + 1, k + 26, this.landType());
		world.setBlock(i + 14, j + 1, k + 27, this.landType());
		world.setBlock(i + 14, j + 1, k + 28, this.landType());
		world.setBlock(i + 14, j + 1, k + 29, this.landType());
		world.setBlock(i + 14, j + 1, k + 30, this.landType());
		world.setBlock(i + 14, j + 1, k + 31, this.landType());
		world.setBlock(i + 14, j + 1, k + 32, this.landType());
		world.setBlock(i + 14, j + 1, k + 33, this.topType());
		world.setBlock(i + 14, j + 2, k + 2, this.topType());
		world.setBlock(i + 14, j + 2, k + 3, this.topType());
		world.setBlock(i + 14, j + 2, k + 4, this.topType());
		world.setBlock(i + 14, j + 2, k + 5, this.topType());
		world.setBlock(i + 14, j + 2, k + 6, this.topType());
		world.setBlock(i + 14, j + 2, k + 7, this.topType());
		world.setBlock(i + 14, j + 2, k + 8, this.topType());
		world.setBlock(i + 14, j + 2, k + 9, this.topType());
		world.setBlock(i + 14, j + 2, k + 10, this.topType());
		world.setBlock(i + 14, j + 2, k + 11, this.topType());
		world.setBlock(i + 14, j + 2, k + 12, this.topType());
		world.setBlock(i + 14, j + 2, k + 13, this.topType());
		world.setBlock(i + 14, j + 2, k + 14, Blocks.double_stone_slab);
		world.setBlock(i + 14, j + 2, k + 15, Blocks.double_stone_slab);
		world.setBlock(i + 14, j + 2, k + 16, Blocks.air);
		world.setBlock(i + 14, j + 2, k + 17, Blocks.air);
		world.setBlock(i + 14, j + 2, k + 19, Blocks.double_stone_slab);
		world.setBlock(i + 14, j + 2, k + 20, Blocks.double_stone_slab);
		world.setBlock(i + 14, j + 2, k + 21, this.topType());
		world.setBlock(i + 14, j + 2, k + 22, this.topType());
		world.setBlock(i + 14, j + 2, k + 23, this.topType());
		world.setBlock(i + 14, j + 2, k + 24, this.topType());
		world.setBlock(i + 14, j + 2, k + 25, this.topType());
		world.setBlock(i + 14, j + 2, k + 26, this.topType());
		world.setBlock(i + 14, j + 2, k + 27, this.topType());
		world.setBlock(i + 14, j + 2, k + 28, this.topType());
